Workbook

Sheet Dashboard Final
B2: TechStore | Sistema de Inteligencia de Negocios | L2: Actualizado: 06/08/2026 · Moneda: USD
B3: Reporte ejecutivo de ventas y margen · Ejercicios 2024-2025
B6: =Calculos!$B$75 -> Las ventas crecen 17.8% y el margen cae 2.5 p.p.: el costo de compra y la logistica del e-commerce se reparten el deterioro
B7: =Calculos!$B$76 -> El margen bruto pasa de 35.8% a 33.3%. La logistica explica 32% del mayor costo y el resto es precio de compra: son dos causas, no una.
B9: VENTAS 2025 | F9: MARGEN BRUTO | J9: CRECIMIENTO INTERANUAL | N9: COSTO LOGISTICO / VENTAS
B10: =Calculos!$B$17 -> 5566045.6 | F10: =Calculos!$B$18 -> 0.33303577 | J10: =Calculos!$B$19 -> 0.17767141 | N10: =Calculos!$B$20 -> 0.033020193
B12: ="vs meta "&TEXT(Calculos!$C$17,"$#,##0")&" "&TEXT(Calculos!$D$17,"+#,##0;-#,##0")&" USD" -> vs meta $5,400,000 +166,046 USD | F12: ="vs meta "&TEXT(Calculos!$C$18,"0.0%")&" "&TEXT(Calculos!$B$21,"+0.0;-0.0")&" p.p. vs 2024" -> vs meta 34.0% -2.5 p.p. vs 2024 | J12: ="vs meta "&TEXT(Calculos!$C$19,"0.0%")&" "&TEXT(Calculos!$D$19*100,"+0.0;-0.0")&" p.p." -> vs meta 15.0% +2.8 p.p. | N12: ="techo "&TEXT(Calculos!$C$20,"0.00%")&" "&TEXT(Calculos!$B$22,"+0.00;-0.00")&" p.p. vs 2024" -> techo 2.50% +1.13 p.p. vs 2024
B13: =Calculos!$D$17 -> 166045.6 | F13: =Calculos!$D$18 -> -0.006964225 | J13: =Calculos!$D$19 -> 0.027671414 | N13: =Calculos!$D$20 -> -0.008020193
B14: FILTROS · los cuatro segmentadores afectan a la vez a los cuatro graficos y a las cuatro tarjetas
B25: QUE PASO Y POR QUE
B47: DONDE MIRAR AHORA
B69: NOTAS DE ANALISIS · conclusiones propias, sometidas a revision critica con IA (ver hoja Analisis_IA)
B70: =Calculos!$B$81 -> 1) El crecimiento es real y de volumen: +17.8% en ventas con +14.4% en unidades. No es un espejismo de precios.
B71: =Calculos!$B$82 -> 2) La caida de margen tiene dos causas, no una: el costo de compra se llevo $172,525 y la logistica $80,921. Atribuirla solo al e-commerce sobreestima su peso.
B72: =Calculos!$B$83 -> 3) La correccion desde el Q3 funciona pero es parcial: el segundo semestre (34.5%) supera al primero (31.8%) y sigue por debajo del mismo periodo de 2024 (35.7%).
B74: Fuente: Ventas_Tech_DB (dataset simulado, 2.400 operaciones). Supuestos y metas en la hoja Parametros. Elaborado por Lleyton Murphy - Coderhouse Data Analyst, Modulo 9.

Sheet Analisis_IA
B2: Analisis asistido por IA - registro del proceso
B3: La IA se uso como auditor cognitivo, no como redactor: primero se escribieron las conclusiones a mano, despues se le pidio que las atacara, y recien al final se corrigio el tablero. El registro completo, con los prompts textuales, esta en el documento anexo.
B5: Conclusion 1 - El crecimiento de 2025 es solido
B6: 1. Conclusion propia | C6: Las ventas pasan de USD 4.726.315 a USD 5.566.046 (+17,8%) y superan la meta de +15%. El negocio crecio.
B7: 2. Prompt de contraste | C7: Actua como analista senior esceptico. Mi conclusion es: "las ventas de una cadena de retail tecnologico crecieron 17,8% interanual, superando la meta de 15%, entonces el negocio crecio". Antes de darme la razon, decime que variables omitidas podrian hacer que esa lectura sea enganosa y que dato concreto tendria que mirar para descartar cada una.
B8: 3. Objecion de la IA | C8: Un alza en pesos no prueba crecimiento del negocio. Puede ser (a) puro efecto precio, (b) cambio de mix hacia productos mas caros, o (c) adelanto de demanda por descuentos agresivos. Pidio contrastar contra unidades.
B9: 4. Verificacion sobre los datos | C9: Las unidades pasan de 25.681 a 29.379 (+14,4%) contra +17,8% en pesos: la mayor parte del crecimiento es volumen y solo unos 3 p.p. vienen de precio. La objecion (a) queda descartada; la (c) queda en pie para Computacion, que tuvo 7% de descuento en el H1.
B10: 5. Cambio en el tablero | C10: La nota 1 del tablero informa ventas Y unidades juntas, para que nadie lea el +17,8% como volumen puro. La conclusion se mantiene, con el matiz.
B12: Conclusion 2 - El margen cae por el costo logistico
B13: 1. Conclusion propia | C13: El margen bruto cae de 35,8% a 33,3% (-2,5 p.p.) mientras el costo logistico sobre ventas sube de 2,18% a 3,30%. La logistica del e-commerce se comio la mejora.
B14: 2. Prompt de contraste | C14: Hace de abogado del diablo con esta conclusion: "el margen cayo 2,5 p.p. y en el mismo periodo el costo logistico paso de 2,18% a 3,30% de las ventas, por el crecimiento del e-commerce; entonces la logistica explica la caida del margen". Buscame el error de logica y decime como descomponer la variacion para probar o refutar la causa.
B15: 3. Objecion de la IA | C15: Falacia de causa unica: el costo logistico subio 1,12 p.p. sobre ventas, o sea menos de la mitad de los 2,5 p.p. perdidos. Que dos cosas se muevan juntas no vuelve a una la causa de la otra. Propuso un puente de margen que separe volumen, precio, costo de compra y logistica.
B16: 4. Verificacion sobre los datos | C16: El puente cierra exacto y desmiente la atribucion: volumen +USD 258.146 y precio +USD 159.153 contra costo de compra -USD 172.525 y logistica -USD 80.921. La logistica explica el 32% del mayor costo, no el total: el costo de compra pesa mas.
B17: 5. Cambio en el tablero | C17: Cambio estructural del tablero. (1) El titular dinamico dejo de decir "el costo logistico se llevo la mejora" y ahora reparte la causa. (2) Se agrego el grafico de cascada justamente para que la descomposicion se vea, en vez de afirmarla. (3) La nota 2 explicita las dos causas con sus montos.
B19: Conclusion 3 - La correccion del Q3 funciono
B20: 1. Conclusion propia | C20: El margen del segundo semestre (34,5%) supera al del primero (31,8%) despues de fijar el umbral de envio minimo en Q3. La medida funciono.
B21: 2. Prompt de contraste | C21: Mi conclusion es: "tras aplicar en Q3 un umbral de envio minimo, el margen del segundo semestre (34,5%) supera al del primero (31,8%), asi que la medida funciono". Decime que sesgos hay en esa lectura y con que comparacion deberia reemplazarla.
B22: 3. Objecion de la IA | C22: Dos problemas. Uno, causalidad asumida: el Q4 es el trimestre mas fuerte del ano (Nov-Dic) y un mix estacional distinto puede subir el margen sin que la medida haya hecho nada. Dos, comparacion contra el periodo equivocado: hay que comparar H2-2025 contra H2-2024, no contra H1-2025.
B23: 4. Verificacion sobre los datos | C23: H2-2024 cerro en 35,7% y H2-2025 en 34,5%: contra el mismo periodo del ano anterior el margen sigue 1,2 p.p. abajo. La recuperacion es real pero parcial, y parte de la mejora es estacional.
B24: 5. Cambio en el tablero | C24: El grafico mensual muestra 2024 y 2025 juntos (no 2025 solo), que es lo unico que deja ver la brecha estacional. El titulo dinamico y la nota 3 dicen "sin volver al nivel de 2024" en lugar de "se recupero".
B26: Que cambio el proceso
B27: Saldo | C27: De las tres conclusiones, una se confirmo con un matiz (la 1), una se refuto en su atribucion causal (la 2) y una se corrigio por comparar contra el periodo equivocado (la 3). El grafico de cascada y la comparativa 2024-2025 del grafico mensual existen por esas objeciones: no estaban en el diseno original.

Sheet Datos
A1: ID_Venta | B1: Fecha | C1: Anio | D1: Trimestre | E1: Mes_Num | F1: Mes | G1: Periodo | H1: Region | I1: Ciudad | J1: Canal | K1: Categoria | L1: Cat_Anio | M1: Producto | N1: Prod_Anio | O1: Unidades | P1: Precio_Unitario | Q1: Costo_Unitario | R1: Ventas | S1: Costo_Producto | T1: Costo_Logistico | U1: Margen_Bruto
A2: 1 | B2: 45299 | C2: 2024 | D2: Q1 | E2: 1 | F2: Ene | G2: 2024-01 | H2: AMBA | I2: Buenos Aires | J2: Tienda fisica | K2: Computacion | L2: Computacion 2024 | M2: Laptop Pro 15 | N2: Laptop Pro 15 2024 | O2: 21 | P2: 1176 | Q2: 744 | R2: =ROUND(O2*P2,2) -> 24696 | S2: =ROUND(O2*Q2,2) -> 15624 | T2: =ROUND(R2*SUMIFS(Parametros!$E$23:$E$38,Parametros!$B$23:$B$38,J2,Parametros!$C$23:$C$38,C2,Parametros!$D$23:$D$38,D2),2) -> 296.35 | U2: =R2-S2-T2 -> 8775.65
A3: 2 | B3: 45306 | C3: 2024 | D3: Q1 | E3: 1 | F3: Ene | G3: 2024-01 | H3: AMBA | I3: Buenos Aires | J3: E-commerce | K3: Computacion | L3: Computacion 2024 | M3: Laptop Pro 15 | N3: Laptop Pro 15 2024 | O3: 8 | P3: 1176 | Q3: 744 | R3: =ROUND(O3*P3,2) -> 9408 | S3: =ROUND(O3*Q3,2) -> 5952 | T3: =ROUND(R3*SUMIFS(Parametros!$E$23:$E$38,Parametros!$B$23:$B$38,J3,Parametros!$C$23:$C$38,C3,Parametros!$D$23:$D$38,D3),2) -> 395.14 | U3: =R3-S3-T3 -> 3060.86
A4: 3 | B4: 45313 | C4: 2024 | D4: Q1 | E4: 1 | F4: Ene | G4: 2024-01 | H4: AMBA | I4: Buenos Aires | J4: Tienda fisica | K4: Computacion | L4: Computacion 2024 | M4: Monitor 4K 27 | N4: Monitor 4K 27 2024 | O4: 18 | P4: 441 | Q4: 272.25 | R4: =ROUND(O4*P4,2) -> 7938 | S4: =ROUND(O4*Q4,2) -> 4900.5 | T4: =ROUND(R4*SUMIFS(Parametros!$E$23:$E$38,Parametros!$B$23:$B$38,J4,Parametros!$C$23:$C$38,C4,Parametros!$D$23:$D$38,D4),2) -> 95.26 | U4: =R4-S4-T4 -> 2942.24
A5: 4 | B5: 45293 | C5: 2024 | D5: Q1 | E5: 1 | F5: Ene | G5: 2024-01 | H5: AMBA | I5: Buenos Aires | J5: E-commerce | K5: Computacion | L5: Computacion 2024 | M5: Monitor 4K 27 | N5: Monitor 4K 27 2024 | O5: 8 | P5: 441 | Q5: 272.25 | R5: =ROUND(O5*P5,2) -> 3528 | S5: =ROUND(O5*Q5,2) -> 2178 | T5: =ROUND(R5*SUMIFS(Parametros!$E$23:$E$38,Parametros!$B$23:$B$38,J5,Parametros!$C$23:$C$38,C5,Parametros!$D$23:$D$38,D5),2) -> 148.18 | U5: =R5-S5-T5 -> 1201.82
A6: 5 | B6: 45300 | C6: 2024 | D6: Q1 | E6: 1 | F6: Ene | G6: 2024-01 | H6: AMBA | I6: Buenos Aires | J6: Tienda fisica | K6: Computacion | L6: Computacion 2024 | M6: PC Gamer Ryzen | N6: PC Gamer Ryzen 2024 | O6: 19 | P6: 1617 | Q6: 1122 | R6: =ROUND(O6*P6,2) -> 30723 | S6: =ROUND(O6*Q6,2) -> 21318 | T6: =ROUND(R6*SUMIFS(Parametros!$E$23:$E$38,Parametros!$B$23:$B$38,J6,Parametros!$C$23:$C$38,C6,Parametros!$D$23:$D$38,D6),2) -> 368.68 | U6: =R6-S6-T6 -> 9036.32
A7: 6 | B7: 45307 | C7: 2024 | D7: Q1 | E7: 1 | F7: Ene | G7: 2024-01 | H7: AMBA | I7: Buenos Aires | J7: E-commerce | K7: Computacion | L7: Computacion 2024 | M7: PC Gamer Ryzen | N7: PC Gamer Ryzen 2024 | O7: 8 | P7: 1617 | Q7: 1122 | R7: =ROUND(O7*P7,2) -> 12936 | S7: =ROUND(O7*Q7,2) -> 8976 | T7: =ROUND(R7*SUMIFS(Parametros!$E$23:$E$38,Parametros!$B$23:$B$38,J7,Parametros!$C$23:$C$38,C7,Parametros!$D$23:$D$38,D7),2) -> 543.31 | U7: =R7-S7-T7 -> 3416.69
A8: 7 | B8: 45314 | C8: 2024 | D8: Q1 | E8: 1 | F8: Ene | G8: 2024-01 | H8: AMBA | I8: Buenos Aires | J8: Tienda fisica | K8: Accesorios | L8: Accesorios 2024 | M8: Mouse Inalambrico | N8: Mouse Inalambrico 2024 | O8: 91 | P8: 27.44 | Q8: 13.44 | R8: =ROUND(O8*P8,2) -> 2497.04 | S8: =ROUND(O8*Q8,2) -> 1223.04 | T8: =ROUND(R8*SUMIFS(Parametros!$E$23:$E$38,Parametros!$B$23:$B$38,J8,Parametros!$C$23:$C$38,C8,Parametros!$D$23:$D$38,D8),2) -> 29.96 | U8: =R8-S8-T8 -> 1244.04
A9: 8 | B9: 45294 | C9: 2024 | D9: Q1 | E9: 1 | F9: Ene | G9: 2024-01 | H9: AMBA | I9: Buenos Aires | J9: E-commerce | K9: Accesorios | L9: Accesorios 2024 | M9: Mouse Inalambrico | N9: Mouse Inalambrico 2024 | O9: 30 | P9: 27.44 | Q9: 13.44 | R9: =ROUND(O9*P9,2) -> 823.2 | S9: =ROUND(O9*Q9,2) -> 403.2 | T9: =ROUND(R9*SUMIFS(Parametros!$E$23:$E$38,Parametros!$B$23:$B$38,J9,Parametros!$C$23:$C$38,C9,Parametros!$D$23:$D$38,D9),2) -> 34.57 | U9: =R9-S9-T9 -> 385.43
A10: 9 | B10: 45301 | C10: 2024 | D10: Q1 | E10: 1 | F10: Ene | G10: 2024-01 | H10: AMBA | I10: Buenos Aires | J10: Tienda fisica | K10: Accesorios | L10: Accesorios 2024 | M10: Teclado Mecanico | N10: Teclado Mecanico 2024 | O10: 95 | P10: 93.1 | Q10: 47.98 | R10: =ROUND(O10*P10,2) -> 8844.5 | S10: =ROUND(O10*Q10,2) -> 4558.1 | T10: =ROUND(R10*SUMIFS(Parametros!$E$23:$E$38,Parametros!$B$23:$B$38,J10,Parametros!$C$23:$C$38,C10,Parametros!$D$23:$D$38,D10),2) -> 106.13 | U10: =R10-S10-T10 -> 4180.27
A11: 10 | B11: 45308 | C11: 2024 | D11: Q1 | E11: 1 | F11: Ene | G11: 2024-01 | H11: AMBA | I11: Buenos Aires | J11: E-commerce | K11: Accesorios | L11: Accesorios 2024 | M11: Teclado Mecanico | N11: Teclado Mecanico 2024 | O11: 35 | P11: 93.1 | Q11: 47.98 | R11: =ROUND(O11*P11,2) -> 3258.5 | S11: =ROUND(O11*Q11,2) -> 1679.3 | T11: =ROUND(R11*SUMIFS(Parametros!$E$23:$E$38,Parametros!$B$23:$B$38,J11,Parametros!$C$23:$C$38,C11,Parametros!$D$23:$D$38,D11),2) -> 136.86 | U11: =R11-S11-T11 -> 1442.34
A12: 11 | B12: 45315 | C12: 2024 | D12: Q1 | E12: 1 | F12: Ene | G12: 2024-01 | H12: AMBA | I12: Buenos Aires | J12: Tienda fisica | K12: Accesorios | L12: Accesorios 2024 | M12: Webcam Full HD | N12: Webcam Full HD 2024 | O12: 98 | P12: 63.7 | Q12: 35.43 | R12: =ROUND(O12*P12,2) -> 6242.6 | S12: =ROUND(O12*Q12,2) -> 3472.14 | T12: =ROUND(R12*SUMIFS(Parametros!$E$23:$E$38,Parametros!$B$23:$B$38,J12,Parametros!$C$23:$C$38,C12,Parametros!$D$23:$D$38,D12),2) -> 74.91 | U12: =R12-S12-T12 -> 2695.55
A13: 12 | B13: 45295 | C13: 2024 | D13: Q1 | E13: 1 | F13: Ene | G13: 2024-01 | H13: AMBA | I13: Buenos Aires | J13: E-commerce | K13: Accesorios | L13: Accesorios 2024 | M13: Webcam Full HD | N13: Webcam Full HD 2024 | O13: 32 | P13: 63.7 | Q13: 35.43 | R13: =ROUND(O13*P13,2) -> 2038.4 | S13: =ROUND(O13*Q13,2) -> 1133.76 | T13: =ROUND(R13*SUMIFS(Parametros!$E$23:$E$38,Parametros!$B$23:$B$38,J13,Parametros!$C$23:$C$38,C13,Parametros!$D$23:$D$38,D13),2) -> 85.61 | U13: =R13-S13-T13 -> 819.03
... A2401: 2400 | B2401: 45998 | C2401: 2025 | D2401: Q4 | E2401: 12 | F2401: Dic | G2401: 2025-12 | H2401: NOA | I2401: Tucuman | J2401: E-commerce | K2401: Almacenamiento | L2401: Almacenamiento 2025 | M2401: Pendrive 256GB | N2401: Pendrive 256GB 2025 | O2401: 17 | P2401: 35.14 | Q2401: 18.39 | R2401: =ROUND(O2401*P2401,2) -> 597.38 | S2401: =ROUND(O2401*Q2401,2) -> 312.63 | T2401: =ROUND(R2401*SUMIFS(Parametros!$E$23:$E$38,Parametros!$B$23:$B$38,J2401,Parametros!$C$23:$C$38,C2401,Parametros!$D$23:$D$38,D2401),2) -> 31.06 | U2401: =R2401-S2401-T2401 -> 253.69

Sheet Parametros
B2: Parametros, supuestos y metas
B3: Todo numero fijo del modelo vive en esta hoja. Los calculos del tablero lo referencian; ninguno lo repite escrito a mano.
B5: METAS DEL EJERCICIO 2025
B6: Indicador | C6: Meta | F6: Origen del supuesto
B7: Ventas totales 2025 | C7: 5400000 | F7: Presupuesto comercial aprobado para el ejercicio (dato de negocio).
B8: Margen bruto % | C8: 0.34 | F8: Piso historico de la cadena: el margen 2024 cerro en 35,8%.
B9: Crecimiento interanual de ventas | C9: 0.15 | F9: Objetivo de expansion fijado por la direccion.
B10: Costo logistico sobre ventas | C10: 0.025 | F10: Techo tolerado; 2024 cerro en 2,18%.
B11: Margen bruto % minimo por producto | C11: 0.33 | F11: Corte usado en el grafico de dispersion para marcar la zona de riesgo.
B14: SUPUESTOS DEL DATASET SIMULADO
B15: Periodo cubierto | C15: Ene-2024 a Dic-2025 | F15: Dataset SIMULADO con semilla fija. Extiende el modelo Ventas_Tech_DB del checkpoint de SQL (mismas categorias, productos y ciudades) a 24 meses, 5 regiones y 2 canales.
B16: Filas de la tabla de hechos | C16: 2400
B17: Aumento de precio de lista 2025 | C17: 0.035
B18: Inflacion de costo de compra 2025 | C18: 0.03
B19: Crecimiento de unidades 2025 | C19: 0.155
B20: Participacion de e-commerce 2024 | C20: 0.28
B21: COSTO LOGISTICO SOBRE VENTAS (tasa aplicada en Datos)
B22: Canal | C22: Anio | D22: Trimestre | E22: Tasa
B23: Tienda fisica | C23: 2024 | D23: Q1 | E23: 0.012 | F23: El salto de e-commerce en 2025 (ultima milla y envio bonificado) y su baja en Q3-Q4 al fijar un umbral de envio minimo es el hecho que explica la caida y posterior recuperacion del margen.
B24: Tienda fisica | C24: 2024 | D24: Q2 | E24: 0.012
B25: Tienda fisica | C25: 2024 | D25: Q3 | E25: 0.013
B26: Tienda fisica | C26: 2024 | D26: Q4 | E26: 0.013
B27: Tienda fisica | C27: 2025 | D27: Q1 | E27: 0.013
B28: Tienda fisica | C28: 2025 | D28: Q2 | E28: 0.014
B29: Tienda fisica | C29: 2025 | D29: Q3 | E29: 0.013
B30: Tienda fisica | C30: 2025 | D30: Q4 | E30: 0.013
B31: E-commerce | C31: 2024 | D31: Q1 | E31: 0.042
B32: E-commerce | C32: 2024 | D32: Q2 | E32: 0.044
B33: E-commerce | C33: 2024 | D33: Q3 | E33: 0.046
B34: E-commerce | C34: 2024 | D34: Q4 | E34: 0.048
B35: E-commerce | C35: 2025 | D35: Q1 | E35: 0.068
... B38: E-commerce | C38: 2025 | D38: Q4 | E38: 0.052

Sheet Guia_de_uso
B2: Guia de uso del tablero
B4: Como se lee | C4: De arriba hacia abajo: el titular dice que paso, las cuatro tarjetas lo cuantifican contra la meta, los dos graficos de arriba explican por que, y los dos de abajo indican donde actuar.
B5: Los segmentadores | C5: Trimestre, Categoria, Region y Canal. Los cuatro estan conectados al mismo cache de tablas dinamicas, asi que cualquier seleccion recalcula a la vez las tarjetas y los cuatro graficos.
B6: Por que Trimestre y no Ano | C6: El filtro de tiempo es el trimestre justamente para no romper la comparacion interanual: al elegir Q1 se comparan Q1-2024 contra Q1-2025. Un filtro de ano dejaria sin sentido el KPI de crecimiento.
B7: Como viaja el filtro | C7: Segmentador -> tabla dinamica (hoja Pivots) -> GETPIVOTDATA (hoja Calculos) -> grafico. Pivots y Calculos estan ocultas a proposito: son soporte, no lectura.
B8: Si los numeros no se mueven | C8: Datos > Actualizar todo. El libro fuerza el recalculo al abrir, pero algunos visores de terceros no ejecutan tablas dinamicas.
B9: Paleta | C9: Tres colores: azul institucional (valor principal y ano corriente), gris (contexto y ano anterior) y ambar (alerta y efectos que restan). Nada mas.
B10: Origen de los datos | C10: Dataset simulado y determinista que extiende el modelo Ventas_Tech_DB del checkpoint de SQL. Todos los supuestos estan en la hoja Parametros.

Sheet Calculos
A1: Capa intermedia del tablero
A2: Cadena del filtro: segmentador -> tabla dinamica (Pivots) -> GETPIVOTDATA (esta hoja) -> grafico del tablero.
A3: Totales por ejercicio | B3: 2024 | C3: 2025
A4: Ventas | B4: =IFERROR(GETPIVOTDATA("Ventas",Pivots!$S$3,"Anio",2024),0) -> 4726314.6 | C4: =IFERROR(GETPIVOTDATA("Ventas",Pivots!$S$3,"Anio",2025),0) -> 5566045.6
A5: Costo de producto | B5: =IFERROR(GETPIVOTDATA("CostoProd",Pivots!$AB$3,"Anio",2024),0) -> 2933604.2 | C5: =IFERROR(GETPIVOTDATA("CostoProd",Pivots!$AB$3,"Anio",2025),0) -> 3528561.4
A6: Costo logistico | B6: =IFERROR(GETPIVOTDATA("CostoLog",Pivots!$AE$3,"Anio",2024),0) -> 102871.35 | C6: =IFERROR(GETPIVOTDATA("CostoLog",Pivots!$AE$3,"Anio",2025),0) -> 183791.9
A7: Margen bruto | B7: =IFERROR(GETPIVOTDATA("Margen",Pivots!$V$3,"Anio",2024),0) -> 1689839 | C7: =IFERROR(GETPIVOTDATA("Margen",Pivots!$V$3,"Anio",2025),0) -> 1853692.3
A8: Unidades | B8: =IFERROR(GETPIVOTDATA("Unidades",Pivots!$Y$3,"Anio",2024),0) -> 25681 | C8: =IFERROR(GETPIVOTDATA("Unidades",Pivots!$Y$3,"Anio",2025),0) -> 29379
A9: Margen bruto % | B9: =IFERROR(B7/B4,0) -> 0.35753841 | C9: =IFERROR(C7/C4,0) -> 0.33303577
A10: Precio promedio por unidad | B10: =IFERROR(B4/B8,0) -> 184.03935 | C10: =IFERROR(C4/C8,0) -> 189.45661
A11: Costo de producto por unidad | B11: =IFERROR(B5/B8,0) -> 114.23248 | C11: =IFERROR(C5/C8,0) -> 120.10488
A12: Margen unitario | B12: =B10-B11 -> 69.806876 | C12: =C10-C11 -> 69.351721
A13: Costo logistico / ventas | B13: =IFERROR(B6/B4,0) -> 0.021765659 | C13: =IFERROR(C6/C4,0) -> 0.033020193
A16: KPI | B16: Valor | C16: Meta | D16: Brecha | E16: Cumple
A17: Ventas 2025 | B17: =C4 -> 5566045.6 | C17: =Parametros!$C$7 -> 5400000 | D17: =B17-C17 -> 166045.6 | E17: =IF(D17>=0,"EN META","BAJO META") -> EN META
A18: Margen bruto % | B18: =C9 -> 0.33303577 | C18: =Parametros!$C$8 -> 0.34 | D18: =B18-C18 -> -0.006964225 | E18: =IF(D18>=0,"EN META","BAJO META") -> BAJO META
A19: Crecimiento interanual | B19: =IFERROR(C4/B4-1,0) -> 0.17767141 | C19: =Parametros!$C$9 -> 0.15 | D19: =B19-C19 -> 0.027671414 | E19: =IF(D19>=0,"EN META","BAJO META") -> EN META
A20: Costo logistico / ventas | B20: =C13 -> 0.033020193 | C20: =Parametros!$C$10 -> 0.025 | D20: =C20-B20 -> -0.008020193 | E20: =IF(D20>=0,"EN META","BAJO META") -> BAJO META
A21: Variacion del margen % (p.p.) | B21: =(C9-B9)*100 -> -2.450264
A22: Variacion del costo logistico / ventas (p.p.) | B22: =(C13-B13)*100 -> 1.1254534
A27: Puente de margen bruto 2024 -> 2025 | B27: Efecto | C27: Acumulado | D27: Base | E27: Total | F27: Suma | G27: Resta
A28: Margen bruto 2024 | B28: =B7 -> 1689839 | C28: =B28 -> 1689839 | D28: 0 | E28: =B28 -> 1689839 | F28: 0 | G28: 0
A29: Mas unidades vendidas | B29: =(C8-B8)*B12 -> 258145.83 | C29: =C28+B29 -> 1947984.9 | D29: =MIN(C28,C29) -> 1689839 | E29: 0 | F29: =MAX(B29,0) -> 258145.83 | G29: =-MIN(B29,0) -> 0
A30: Precios de venta mas altos | B30: =(C10-B10)*C8 -> 159153.48 | C30: =C29+B30 -> 2107138.3 | D30: =MIN(C29,C30) -> 1947984.9 | E30: 0 | F30: =MAX(B30,0) -> 159153.48 | G30: =-MIN(B30,0) -> 0
A31: Costo de compra mas caro | B31: =-(C11-B11)*C8 -> -172525.47 | C31: =C30+B31 -> 1934612.9 | D31: =MIN(C30,C31) -> 1934612.9 | E31: 0 | F31: =MAX(B31,0) -> 0 | G31: =-MIN(B31,0) -> 172525.47
A32: Costo logistico mas caro | B32: =-(C6-B6) -> -80920.55 | C32: =C31+B32 -> 1853692.3 | D32: =MIN(C31,C32) -> 1853692.3 | E32: 0 | F32: =MAX(B32,0) -> 0 | G32: =-MIN(B32,0) -> 80920.55
A33: Margen bruto 2025 | B33: =C7 -> 1853692.3 | C33: =B33 -> 1853692.3 | D33: 0 | E33: =B33 -> 1853692.3 | F33: 0 | G33: 0
A34: Control: los efectos deben cerrar en cero | B34: =ROUND(SUM(B28:B32)-B33,2) -> 0
A37: Evolucion mensual | B37: Ventas 2024 | C37: Ventas 2025 | D37: Margen % 2025 | E37: Margen 2025 | F37: Margen 2024
A38: Ene | B38: =IFERROR(GETPIVOTDATA("Ventas",Pivots!$A$3,"Periodo","2024-01"),0) -> 335709.78 | C38: =IFERROR(GETPIVOTDATA("Ventas",Pivots!$A$3,"Periodo","2025-01"),0) -> 376115.96 | D38: =IFERROR(E38/C38,0) -> 0.3184905 | E38: =IFERROR(GETPIVOTDATA("Margen",Pivots!$D$3,"Periodo","2025-01"),0) -> 119789.36 | F38: =IFERROR(GETPIVOTDATA("Margen",Pivots!$D$3,"Periodo","2024-01"),0) -> 120067.45
A39: Feb | B39: =IFERROR(GETPIVOTDATA("Ventas",Pivots!$A$3,"Periodo","2024-02"),0) -> 297385.9 | C39: =IFERROR(GETPIVOTDATA("Ventas",Pivots!$A$3,"Periodo","2025-02"),0) -> 354148.74 | D39: =IFERROR(E39/C39,0) -> 0.32058482 | E39: =IFERROR(GETPIVOTDATA("Margen",Pivots!$D$3,"Periodo","2025-02"),0) -> 113534.71 | F39: =IFERROR(GETPIVOTDATA("Margen",Pivots!$D$3,"Periodo","2024-02"),0) -> 106798.53
A40: Mar | B40: =IFERROR(GETPIVOTDATA("Ventas",Pivots!$A$3,"Periodo","2024-03"),0) -> 362339.32 | C40: =IFERROR(GETPIVOTDATA("Ventas",Pivots!$A$3,"Periodo","2025-03"),0) -> 424353.81 | D40: =IFERROR(E40/C40,0) -> 0.31919383 | E40: =IFERROR(GETPIVOTDATA("Margen",Pivots!$D$3,"Periodo","2025-03"),0) -> 135451.12 | F40: =IFERROR(GETPIVOTDATA("Margen",Pivots!$D$3,"Periodo","2024-03"),0) -> 129801.25
A41: Abr | B41: =IFERROR(GETPIVOTDATA("Ventas",Pivots!$A$3,"Periodo","2024-04"),0) -> 351882.72 | C41: =IFERROR(GETPIVOTDATA("Ventas",Pivots!$A$3,"Periodo","2025-04"),0) -> 401046.29 | D41: =IFERROR(E41/C41,0) -> 0.31838063 | E41: =IFERROR(GETPIVOTDATA("Margen",Pivots!$D$3,"Periodo","2025-04"),0) -> 127685.37 | F41: =IFERROR(GETPIVOTDATA("Margen",Pivots!$D$3,"Periodo","2024-04"),0) -> 126288.28
A42: May | B42: =IFERROR(GETPIVOTDATA("Ventas",Pivots!$A$3,"Periodo","2024-05"),0) -> 379787.24 | C42: =IFERROR(GETPIVOTDATA("Ventas",Pivots!$A$3,"Periodo","2025-05"),0) -> 447928.5 | D42: =IFERROR(E42/C42,0) -> 0.31447646 | E42: =IFERROR(GETPIVOTDATA("Margen",Pivots!$D$3,"Periodo","2025-05"),0) -> 140862.97 | F42: =IFERROR(GETPIVOTDATA("Margen",Pivots!$D$3,"Periodo","2024-05"),0) -> 135657.89
A43: Jun | B43: =IFERROR(GETPIVOTDATA("Ventas",Pivots!$A$3,"Periodo","2024-06"),0) -> 402575.18 | C43: =IFERROR(GETPIVOTDATA("Ventas",Pivots!$A$3,"Periodo","2025-06"),0) -> 466752.11 | D43: =IFERROR(E43/C43,0) -> 0.31764996 | E43: =IFERROR(GETPIVOTDATA("Margen",Pivots!$D$3,"Periodo","2025-06"),0) -> 148263.79 | F43: =IFERROR(GETPIVOTDATA("Margen",Pivots!$D$3,"Periodo","2024-06"),0) -> 144262.33
A44: Jul | B44: =IFERROR(GETPIVOTDATA("Ventas",Pivots!$A$3,"Periodo","2024-07"),0) -> 421091.3 | C44: =IFERROR(GETPIVOTDATA("Ventas",Pivots!$A$3,"Periodo","2025-07"),0) -> 500057.9 | D44: =IFERROR(E44/C44,0) -> 0.34359389 | E44: =IFERROR(GETPIVOTDATA("Margen",Pivots!$D$3,"Periodo","2025-07"),0) -> 171816.84 | F44: =IFERROR(GETPIVOTDATA("Margen",Pivots!$D$3,"Periodo","2024-07"),0) -> 150294.12
A45: Ago | B45: =IFERROR(GETPIVOTDATA("Ventas",Pivots!$A$3,"Periodo","2024-08"),0) -> 369456.08 | C45: =IFERROR(GETPIVOTDATA("Ventas",Pivots!$A$3,"Periodo","2025-08"),0) -> 444999.85 | D45: =IFERROR(E45/C45,0) -> 0.34508702 | E45: =IFERROR(GETPIVOTDATA("Margen",Pivots!$D$3,"Periodo","2025-08"),0) -> 153563.67 | F45: =IFERROR(GETPIVOTDATA("Margen",Pivots!$D$3,"Periodo","2024-08"),0) -> 132020.34
A46: Sep | B46: =IFERROR(GETPIVOTDATA("Ventas",Pivots!$A$3,"Periodo","2024-09"),0) -> 374810.8 | C46: =IFERROR(GETPIVOTDATA("Ventas",Pivots!$A$3,"Periodo","2025-09"),0) -> 445706.66 | D46: =IFERROR(E46/C46,0) -> 0.344371 | E46: =IFERROR(GETPIVOTDATA("Margen",Pivots!$D$3,"Periodo","2025-09"),0) -> 153488.45 | F46: =IFERROR(GETPIVOTDATA("Margen",Pivots!$D$3,"Periodo","2024-09"),0) -> 133911.95
A47: Oct | B47: =IFERROR(GETPIVOTDATA("Ventas",Pivots!$A$3,"Periodo","2024-10"),0) -> 400237.88 | C47: =IFERROR(GETPIVOTDATA("Ventas",Pivots!$A$3,"Periodo","2025-10"),0) -> 466416.5 | D47: =IFERROR(E47/C47,0) -> 0.34605639 | E47: =IFERROR(GETPIVOTDATA("Margen",Pivots!$D$3,"Periodo","2025-10"),0) -> 161406.41 | F47: =IFERROR(GETPIVOTDATA("Margen",Pivots!$D$3,"Periodo","2024-10"),0) -> 142640.53
A48: Nov | B48: =IFERROR(GETPIVOTDATA("Ventas",Pivots!$A$3,"Periodo","2024-11"),0) -> 474654.18 | C48: =IFERROR(GETPIVOTDATA("Ventas",Pivots!$A$3,"Periodo","2025-11"),0) -> 567804.81 | D48: =IFERROR(E48/C48,0) -> 0.34586562 | E48: =IFERROR(GETPIVOTDATA("Margen",Pivots!$D$3,"Periodo","2025-11"),0) -> 196384.16 | F48: =IFERROR(GETPIVOTDATA("Margen",Pivots!$D$3,"Periodo","2024-11"),0) -> 169647.46
...

Sheet Pivots
A1: Tablas dinamicas de soporte. Los segmentadores del tablero filtran estas tablas y los graficos las leen con GETPIVOTDATA. No editar a mano.
A3: Periodo | B3: Ventas | D3: Periodo | E3: Margen | G3: Cat_Anio | H3: Ventas | J3: Cat_Anio | K3: Margen | M3: Prod_Anio | N3: Ventas | P3: Prod_Anio | Q3: Margen | S3: Anio | T3: Ventas | V3: Anio | W3: Margen | Y3: Anio | Z3: Unidades | AB3: Anio | AC3: CostoProd | AE3: Anio | AF3: CostoLog | AH3: Region | AI3: Ventas
A4: 2024-01 | B4: 335709.78 | D4: 2024-01 | E4: 120067.45 | G4: Computacion 2024 | H4: 3067155 | J4: Computacion 2024 | K4: 974230.43 | M4: Laptop Pro 15 2024 | N4: 1139544 | P4: Laptop Pro 15 2024 | Q4: 393830.85 | S4: 2024 | T4: 4726314.6 | V4: 2024 | W4: 1689839 | Y4: 2024 | Z4: 25681 | AB4: 2024 | AC4: 2933604.2 | AE4: 2024 | AF4: 102871.35 | AH4: AMBA | AI4: 3896685.1
A5: 2024-02 | B5: 297385.9 | D5: 2024-02 | E5: 106798.53 | G5: Accesorios 2024 | H5: 834602.3 | J5: Accesorios 2024 | K5: 377790.13 | M5: Monitor 4K 27 2024 | N5: 423801 | P5: Monitor 4K 27 2024 | Q5: 153039.62 | S5: 2025 | T5: 5566045.6 | V5: 2025 | W5: 1853692.3 | Y5: 2025 | Z5: 29379 | AB5: 2025 | AC5: 3528561.4 | AE5: 2025 | AF5: 183791.9 | AH5: Centro | AI5: 2262766.3
A6: 2024-03 | B6: 362339.32 | D6: 2024-03 | E6: 129801.25 | G6: Audio 2024 | H6: 402936.8 | J6: Audio 2024 | K6: 170199.36 | M6: PC Gamer Ryzen 2024 | N6: 1503810 | P6: PC Gamer Ryzen 2024 | Q6: 427359.96 | S6: Total Result | T6: 10292360 | V6: Total Result | W6: 3543531.3 | Y6: Total Result | Z6: 55060 | AB6: Total Result | AC6: 6462165.6 | AE6: Total Result | AF6: 286663.25 | AH6: Litoral | AI6: 1655093.7
A7: 2024-04 | B7: 351882.72 | D7: 2024-04 | E7: 126288.28 | G7: Almacenamiento 2024 | H7: 421620.5 | J7: Almacenamiento 2024 | K7: 167619.11 | M7: Mouse Inalambrico 2024 | N7: 123891.6 | P7: Mouse Inalambrico 2024 | Q7: 60540.18 | AH7: Cuyo | AI7: 1247848.4
A8: 2024-05 | B8: 379787.24 | D8: 2024-05 | E8: 135657.89 | G8: Computacion 2025 | H8: 3629530.2 | J8: Computacion 2025 | K8: 1051612.1 | M8: Teclado Mecanico 2024 | N8: 420812 | P8: Teclado Mecanico 2024 | Q8: 194829.25 | AH8: NOA | AI8: 1229966.7
A9: 2024-06 | B9: 402575.18 | D9: 2024-06 | E9: 144262.33 | G9: Accesorios 2025 | H9: 963729.38 | J9: Accesorios 2025 | K9: 419940.2 | M9: Webcam Full HD 2024 | N9: 289898.7 | P9: Webcam Full HD 2024 | Q9: 122420.7 | AH9: Total Result | AI9: 10292360
A10: 2024-07 | B10: 421091.3 | D10: 2024-07 | E10: 150294.12 | G10: Audio 2025 | H10: 480609.25 | J10: Audio 2025 | K10: 194901.36 | M10: Auriculares BT Pro 2024 | N10: 233671.2 | P10: Auriculares BT Pro 2024 | Q10: 102216.65
A11: 2024-08 | B11: 369456.08 | D11: 2024-08 | E11: 132020.34 | G11: Almacenamiento 2025 | H11: 492176.82 | J11: Almacenamiento 2025 | K11: 187238.69 | M11: Parlante Bluetooth 2024 | N11: 169265.6 | P11: Parlante Bluetooth 2024 | Q11: 67982.71
A12: 2024-09 | B12: 374810.8 | D12: 2024-09 | E12: 133911.95 | G12: Total Result | H12: 10292360 | J12: Total Result | K12: 3543531.3 | M12: SSD Externo 1TB 2024 | N12: 332131.8 | P12: SSD Externo 1TB 2024 | Q12: 126653.78
A13: 2024-10 | B13: 400237.88 | D13: 2024-10 | E13: 142640.53 | M13: Pendrive 256GB 2024 | N13: 89488.7 | P13: Pendrive 256GB 2024 | Q13: 40965.33
A14: 2024-11 | B14: 474654.18 | D14: 2024-11 | E14: 169647.46 | M14: Laptop Pro 15 2025 | N14: 1313626.1 | P14: Laptop Pro 15 2025 | Q14: 419236.65
A15: 2024-12 | B15: 556384.22 | D15: 2024-12 | E15: 198448.9 | M15: Monitor 4K 27 2025 | N15: 498411.2 | P15: Monitor 4K 27 2025 | Q15: 166561.95
A16: 2025-01 | B16: 376115.96 | D16: 2025-01 | E16: 119789.36 | M16: PC Gamer Ryzen 2025 | N16: 1817492.8 | P16: PC Gamer Ryzen 2025 | Q16: 465813.46
A17: 2025-02 | B17: 354148.74 | D17: 2025-02 | E17: 113534.71 | M17: Mouse Inalambrico 2025 | N17: 142604.16 | P17: Mouse Inalambrico 2025 | Q17: 67372.65
A18: 2025-03 | B18: 424353.81 | D18: 2025-03 | E18: 135451.12 | M18: Teclado Mecanico 2025 | N18: 490311.2 | P18: Teclado Mecanico 2025 | Q18: 218656.89
A19: 2025-04 | B19: 401046.29 | D19: 2025-04 | E19: 127685.37 | M19: Webcam Full HD 2025 | N19: 330814.02 | P19: Webcam Full HD 2025 | Q19: 133910.66
A20: 2025-05 | B20: 447928.5 | D20: 2025-05 | E20: 140862.97 | M20: Auriculares BT Pro 2025 | N20: 282858.21 | P20: Auriculares BT Pro 2025 | Q20: 118980.84
A21: 2025-06 | B21: 466752.11 | D21: 2025-06 | E21: 148263.79 | M21: Parlante Bluetooth 2025 | N21: 197751.04 | P21: Parlante Bluetooth 2025 | Q21: 75920.52
A22: 2025-07 | B22: 500057.9 | D22: 2025-07 | E22: 171816.84 | M22: SSD Externo 1TB 2025 | N22: 387109.46 | P22: SSD Externo 1TB 2025 | Q22: 140881.09
A23: 2025-08 | B23: 444999.85 | D23: 2025-08 | E23: 153563.67 | M23: Pendrive 256GB 2025 | N23: 105067.36 | P23: Pendrive 256GB 2025 | Q23: 46357.6
A24: 2025-09 | B24: 445706.66 | D24: 2025-09 | E24: 153488.45 | M24: Total Result | N24: 10292360 | P24: Total Result | Q24: 3543531.3
A25: 2025-10 | B25: 466416.5 | D25: 2025-10 | E25: 161406.41
A26: 2025-11 | B26: 567804.81 | D26: 2025-11 | E26: 196384.16
A27: 2025-12 | B27: 670714.47 | D27: 2025-12 | E27: 231445.46
A28: Total Result | B28: 10292360 | D28: Total Result | E28: 3543531.3
