Workbook

Sheet Dashboard
B2: TechStore | Reporte ejecutivo de ventas y margen | L2: Actualizado: 06/08/2026 · Moneda: USD
B3: Ejercicios 2024-2025 · 2.400 operaciones depuradas · 5 regiones · 2 canales
B6: =Calculos!$B$85 -> Las ventas crecen 17.8% y el margen cae 2.4 p.p.: el costo de compra y la logistica del e-commerce se reparten el deterioro
B7: =Calculos!$B$86 -> El margen bruto pasa de 35.8% a 33.3%. La logistica explica 32% del mayor costo y el resto es precio de compra: son dos causas, no una.
B9: VENTAS 2025 | F9: MARGEN BRUTO | J9: CRECIMIENTO INTERANUAL | N9: COSTO LOGISTICO / VENTAS
B10: =Calculos!$B$17 -> 5566045.6 | F10: =Calculos!$B$18 -> 0.33303577 | J10: =Calculos!$B$19 -> 0.17767141 | N10: =Calculos!$B$20 -> 0.033020193
B12: ="vs meta "&TEXT(Calculos!$C$17,"$#,##0")&" "&TEXT(Calculos!$D$17,"+#,##0;-#,##0")&" USD" -> vs meta $5,400,000 +166,046 USD | F12: ="vs meta "&TEXT(Calculos!$C$18,"0.0%")&" "&TEXT(Calculos!$B$21,"+0.0;-0.0")&" p.p. vs 2024" -> vs meta 34.0% -2.4 p.p. vs 2024 | J12: ="vs meta "&TEXT(Calculos!$C$19,"0.0%")&" "&TEXT(Calculos!$D$19*100,"+0.0;-0.0")&" p.p." -> vs meta 15.0% +2.8 p.p. | N12: ="techo "&TEXT(Calculos!$C$20,"0.00%")&" "&TEXT(Calculos!$B$22,"+0.00;-0.00")&" p.p. vs 2024" -> techo 2.50% +1.13 p.p. vs 2024
B13: =Calculos!$D$17 -> 166045.6 | F13: =Calculos!$D$18 -> -0.006964225 | J13: =Calculos!$D$19 -> 0.027671414 | N13: =Calculos!$D$20 -> -0.008020193
B14: FILTROS · cualquier seleccion recalcula a la vez las cuatro tarjetas y los cinco graficos
B25: 1 · QUE PASO · evolucion de las ventas y del margen
B44: 2 · POR QUE · de donde sale la caida del margen
B63: 3 · DONDE ACTUAR · que productos miran primero
B82: =Calculos!$B$95 -> Zona de riesgo (margen por debajo de 33%): Laptop Pro 15, PC Gamer Ryzen. El resto de los productos esta en meta.
B84: REPORTE EJECUTIVO · cada linea dice primero el dato y despues que hacer con el
B85: =Calculos!$B$92 -> EVIDENCIA: las ventas suben 17.8% y las unidades 14.4%. INSIGHT: el crecimiento es de volumen, no de precio, asi que la demanda es real y conviene sostener el plan comercial.
B87: =Calculos!$B$93 -> EVIDENCIA: el costo de compra resta $172,502 y la logistica $80,921 de margen. INSIGHT: la caida tiene dos causas, no una; atribuirla solo al e-commerce sobreestima su peso y desviaria el presupuesto de correccion.
B89: =Calculos!$B$94 -> EVIDENCIA: el segundo semestre (34.5%) supera al primero (31.8%) pero sigue por debajo del mismo periodo de 2024 (35.7%). INSIGHT: la correccion del Q3 funciona pero es parcial; hay que sostenerla en el proximo semestre antes de fijar nuevas metas.
B92: Fuente: export del sistema transaccional depurado en este mismo libro (hojas Datos_Origen -> Datos_Limpios -> Control_Calidad). Metas y supuestos en la hoja Parametros. Dataset simulado con fines academicos. Elaborado por Lleyton Murphy · Coderhouse, Data Analyst · Practica Integradora Final.

Sheet Tablas_Dinamicas
B2: Tablas dinamicas del reporte | L2: Como leer esta hoja
B3: Las cuatro resumen la tabla de hechos depurada y comparten el mismo cache: los segmentadores del tablero las filtran a todas a la vez. Los graficos del dashboard leen exactamente estos numeros.
L4: Las cuatro tablas salen del mismo cache de datos, asi que los cuatro segmentadores del tablero (Trimestre, Categoria, Region y Canal) las filtran simultaneamente.
B5: 1 · Ventas, margen y unidades por REGION | G5: 2 · Ventas, margen y unidades por CATEGORIA
C6: Valores | H6: Valores
B7: Region | C7: Ventas | D7: Margen | E7: Unidades | G7: Categoria | H7: Ventas | I7: Margen | J7: Unidades
B8: AMBA | C8: 3896685.1 | D8: 1341318.3 | E8: 20839 | G8: Computacion | H8: 6696685.1 | I8: 2025842.5 | J8: 6213
B9: Centro | C9: 2262766.3 | D9: 780708.6 | E9: 12174 | G9: Accesorios | H9: 1798331.7 | I9: 797730.33 | J9: 28941 | L9: La tabla 4 resume una columna que no existe en el origen: Segmento_Rentabilidad se calcula con SI/Y/O en Datos_Limpios contra los umbrales de Parametros.
B10: Litoral | C10: 1655093.7 | D10: 569389.84 | E10: 8826 | G10: Audio | H10: 883546.05 | I10: 365080.4 | J10: 8706
B11: Cuyo | C11: 1247848.4 | D11: 427843.83 | E11: 6595 | G11: Almacenamiento | H11: 913797.32 | I11: 354857.8 | J11: 11200
B12: NOA | C12: 1229966.7 | D12: 424250.41 | E12: 6626 | G12: Total general | H12: 10292360 | I12: 3543511 | J12: 55060
B13: Total general | C13: 10292360 | D13: 3543511 | E13: 55060
L14: Si los numeros no se mueven al abrir el archivo: Datos > Actualizar todo. El libro pide el refresco al abrir, pero algunos visores de terceros no ejecutan tablas dinamicas.
B15: 3 · Ventas, margen y unidades por PRODUCTO | G15: 4 · Ventas y unidades por SEGMENTO DE RENTABILIDAD (columna calculada con SI/Y/O)
C16: Valores | H16: Valores
B17: Producto | C17: Ventas | D17: Margen | E17: Unidades | G17: Segmento_Rentabilidad | H17: Ventas | I17: Unidades
B18: Laptop Pro 15 | C18: 2453170.1 | D18: 813067.5 | E18: 2080 | G18: Alta rentabilidad | H18: 3436432.4 | I18: 21127
B19: Monitor 4K 27 | C19: 922212.2 | D19: 319601.57 | E19: 2085 | G19: Estandar | H19: 4927827.4 | I19: 32390
B20: PC Gamer Ryzen | C20: 3321302.8 | D20: 893173.42 | E20: 2048 | G20: Revisar | H20: 1928100.4 | I20: 1543
B21: Mouse Inalambrico | C21: 266495.76 | D21: 127912.83 | E21: 9612 | G21: Total general | H21: 10292360 | I21: 55060
B22: Teclado Mecanico | C22: 911123.2 | D22: 413486.14 | E22: 9685
B23: Webcam Full HD | C23: 620712.72 | D23: 256331.36 | E23: 9644
B24: Auriculares BT Pro | C24: 516529.41 | D24: 221197.49 | E24: 4346
B25: Parlante Bluetooth | C25: 367016.64 | D25: 143882.91 | E25: 4360
B26: SSD Externo 1TB | C26: 719241.26 | D26: 267534.87 | E26: 5587
B27: Pendrive 256GB | C27: 194556.06 | D27: 87322.93 | E27: 5613
B28: Total general | C28: 10292360 | D28: 3543511 | E28: 55060
B31: CONSULTA PUNTUAL · elegi los valores en las listas desplegables
B32: Complementa a las tablas dinamicas: responde una pregunta concreta sin tocar los filtros del tablero. Las tres celdas azules son listas de validacion; el resto son formulas SUMAR.SI.CONJUNTO sobre Datos_Limpios.
B35: Region | C35: AMBA | D35: Ventas | E35: =SUMIFS(Datos_Limpios!$R$2:$R$2401,Datos_Limpios!$H$2:$H$2401,$C$35,Datos_Limpios!$K$2:$K$2401,$C$36,Datos_Limpios!$C$2:$C$2401,$F$35) -> 2537006.1 | F35: =IF($C$37="Todos",">0","="&$C$37) -> >0
B36: Categoria | C36: Computacion | D36: Margen bruto | E36: =SUMIFS(Datos_Limpios!$U$2:$U$2401,Datos_Limpios!$H$2:$H$2401,$C$35,Datos_Limpios!$K$2:$K$2401,$C$36,Datos_Limpios!$C$2:$C$2401,$F$35) -> 767191.43
B37: Anio | C37: Todos | D37: Unidades | E37: =SUMIFS(Datos_Limpios!$O$2:$O$2401,Datos_Limpios!$H$2:$H$2401,$C$35,Datos_Limpios!$K$2:$K$2401,$C$36,Datos_Limpios!$C$2:$C$2401,$F$35) -> 2366
D38: Margen bruto % | E38: =IFERROR(E36/E35,0) -> 0.30240031
D39: Operaciones | E39: =COUNTIFS(Datos_Limpios!$H$2:$H$2401,$C$35,Datos_Limpios!$K$2:$K$2401,$C$36,Datos_Limpios!$C$2:$C$2401,$F$35) -> 144
B41: Nota: la opcion "Todos" del anio se resuelve con un criterio dinamico (">0") en la celda tecnica F35, para que una misma formula sirva para un anio puntual y para el total.

Sheet Datos_Limpios
A1: ID_Venta | B1: Fecha | C1: Anio | D1: Trimestre | E1: Mes_Num | F1: Mes | G1: Periodo | H1: Region | I1: Ciudad | J1: Canal | K1: Categoria | L1: Cat_Anio | M1: Producto | N1: Prod_Anio | O1: Unidades | P1: Precio_Unitario | Q1: Costo_Unitario | R1: Ventas | S1: Costo_Producto | T1: Costo_Logistico | U1: Margen_Bruto | V1: Margen_Pct | W1: Segmento_Rentabilidad | X1: Alerta_Logistica | Y1: Ticket | Z1: Pos_Origen | AA1: Control_ETL | AB1: Fecha_Origen | AC1: Unidades_Origen | AD1: Ciudad_Origen
A2: =INDEX(Datos_Origen!$A$2:$A$2459,$Z2) -> 1 | B2: =IF(ISNUMBER($AB2),$AB2,IF(MID($AB2,5,1)="-",DATE(VALUE(LEFT($AB2,4)),VALUE(MID($AB2,6,2)),VALUE(RIGHT($AB2,2))),DATE(VALUE(RIGHT($AB2,4)),VALUE(MID($AB2,4,2)),VALUE(LEFT($AB2,2))))) -> 45299 | C2: =YEAR($B2) -> 2024 | D2: ="Q"&ROUNDUP(MONTH($B2)/3,0) -> Q1 | E2: =MONTH($B2) -> 1 | F2: =INDEX(Parametros!$I$5:$I$16,$E2) -> Ene | G2: =TEXT($C2,"0000")&"-"&TEXT($E2,"00") -> 2024-01 | H2: =INDEX(Parametros!$C$71:$C$91,MATCH(TRIM(INDEX(Datos_Origen!$C$2:$C$2459,$Z2)),Parametros!$B$71:$B$91,0)) -> AMBA | I2: =IF(TRIM($AD2)="",INDEX(Parametros!$I$20:$I$24,MATCH($H2,Parametros!$H$20:$H$24,0)),TRIM($AD2)) -> Buenos Aires | J2: =INDEX(Parametros!$C$95:$C$106,MATCH(TRIM(INDEX(Datos_Origen!$E$2:$E$2459,$Z2)),Parametros!$B$95:$B$106,0)) -> Tienda fisica | K2: =INDEX(Parametros!$C$48:$C$67,MATCH(TRIM(INDEX(Datos_Origen!$F$2:$F$2459,$Z2)),Parametros!$B$48:$B$67,0)) -> Computacion | L2: =$K2&" "&$C2 -> Computacion 2024 | M2: =TRIM(INDEX(Datos_Origen!$G$2:$G$2459,$Z2)) -> Laptop Pro 15 | N2: =$M2&" "&$C2 -> Laptop Pro 15 2024 | O2: =IF(ISTEXT($AC2),VALUE($AC2),$AC2) -> 21 | P2: =INDEX(Datos_Origen!$I$2:$I$2459,$Z2) -> 1176 | Q2: =INDEX(Datos_Origen!$J$2:$J$2459,$Z2) -> 744 | R2: =ROUND($O2*$P2,2) -> 24696 | S2: =ROUND($O2*$Q2,2) -> 15624 | T2: =ROUND($R2*SUMIFS(Parametros!$E$28:$E$43,Parametros!$B$28:$B$43,$J2,Parametros!$C$28:$C$43,$C2,Parametros!$D$28:$D$43,$D2),2) -> 296.35 | U2: =$R2-$S2-$T2 -> 8775.65 | V2: =IFERROR($U2/$R2,0) -> 0.35534702 | W2: =IF(AND($V2>=Parametros!$C$8,$R2>=Parametros!$C$12),"Alta rentabilidad",IF(OR($V2<Parametros!$C$11,$R2<Parametros!$C$13),"Revisar","Estandar")) -> Alta rentabilidad | X2: =IF(AND($J2="E-commerce",IFERROR($T2/$R2,0)>Parametros!$C$14),"Alerta","OK") -> OK | Y2: =IF($R2>=Parametros!$C$12,"Alto",IF($R2<Parametros!$C$13,"Bajo","Medio")) -> Alto | Z2: 2024 | AA2: =IF(MATCH($A2,Datos_Origen!$A$2:$A$2459,0)=$Z2,"OK","REVISAR") -> OK | AB2: =INDEX(Datos_Origen!$B$2:$B$2459,$Z2) -> 08/01/2024 | AC2: =INDEX(Datos_Origen!$H$2:$H$2459,$Z2) -> 21 | AD2: =INDEX(Datos_Origen!$D$2:$D$2459,$Z2)&"" -> Buenos Aires
A3: =INDEX(Datos_Origen!$A$2:$A$2459,$Z3) -> 2 | B3: =IF(ISNUMBER($AB3),$AB3,IF(MID($AB3,5,1)="-",DATE(VALUE(LEFT($AB3,4)),VALUE(MID($AB3,6,2)),VALUE(RIGHT($AB3,2))),DATE(VALUE(RIGHT($AB3,4)),VALUE(MID($AB3,4,2)),VALUE(LEFT($AB3,2))))) -> 45306 | C3: =YEAR($B3) -> 2024 | D3: ="Q"&ROUNDUP(MONTH($B3)/3,0) -> Q1 | E3: =MONTH($B3) -> 1 | F3: =INDEX(Parametros!$I$5:$I$16,$E3) -> Ene | G3: =TEXT($C3,"0000")&"-"&TEXT($E3,"00") -> 2024-01 | H3: =INDEX(Parametros!$C$71:$C$91,MATCH(TRIM(INDEX(Datos_Origen!$C$2:$C$2459,$Z3)),Parametros!$B$71:$B$91,0)) -> AMBA | I3: =IF(TRIM($AD3)="",INDEX(Parametros!$I$20:$I$24,MATCH($H3,Parametros!$H$20:$H$24,0)),TRIM($AD3)) -> Buenos Aires | J3: =INDEX(Parametros!$C$95:$C$106,MATCH(TRIM(INDEX(Datos_Origen!$E$2:$E$2459,$Z3)),Parametros!$B$95:$B$106,0)) -> E-commerce | K3: =INDEX(Parametros!$C$48:$C$67,MATCH(TRIM(INDEX(Datos_Origen!$F$2:$F$2459,$Z3)),Parametros!$B$48:$B$67,0)) -> Computacion | L3: =$K3&" "&$C3 -> Computacion 2024 | M3: =TRIM(INDEX(Datos_Origen!$G$2:$G$2459,$Z3)) -> Laptop Pro 15 | N3: =$M3&" "&$C3 -> Laptop Pro 15 2024 | O3: =IF(ISTEXT($AC3),VALUE($AC3),$AC3) -> 8 | P3: =INDEX(Datos_Origen!$I$2:$I$2459,$Z3) -> 1176 | Q3: =INDEX(Datos_Origen!$J$2:$J$2459,$Z3) -> 744 | R3: =ROUND($O3*$P3,2) -> 9408 | S3: =ROUND($O3*$Q3,2) -> 5952 | T3: =ROUND($R3*SUMIFS(Parametros!$E$28:$E$43,Parametros!$B$28:$B$43,$J3,Parametros!$C$28:$C$43,$C3,Parametros!$D$28:$D$43,$D3),2) -> 395.14 | U3: =$R3-$S3-$T3 -> 3060.86 | V3: =IFERROR($U3/$R3,0) -> 0.32534651 | W3: =IF(AND($V3>=Parametros!$C$8,$R3>=Parametros!$C$12),"Alta rentabilidad",IF(OR($V3<Parametros!$C$11,$R3<Parametros!$C$13),"Revisar","Estandar")) -> Estandar | X3: =IF(AND($J3="E-commerce",IFERROR($T3/$R3,0)>Parametros!$C$14),"Alerta","OK") -> OK | Y3: =IF($R3>=Parametros!$C$12,"Alto",IF($R3<Parametros!$C$13,"Bajo","Medio")) -> Alto | Z3: 1401 | AA3: =IF(MATCH($A3,Datos_Origen!$A$2:$A$2459,0)=$Z3,"OK","REVISAR") -> OK | AB3: =INDEX(Datos_Origen!$B$2:$B$2459,$Z3) -> 2024-01-15 | AC3: =INDEX(Datos_Origen!$H$2:$H$2459,$Z3) -> 8 | AD3: =INDEX(Datos_Origen!$D$2:$D$2459,$Z3)&"" -> Buenos Aires
A4: =INDEX(Datos_Origen!$A$2:$A$2459,$Z4) -> 3 | B4: =IF(ISNUMBER($AB4),$AB4,IF(MID($AB4,5,1)="-",DATE(VALUE(LEFT($AB4,4)),VALUE(MID($AB4,6,2)),VALUE(RIGHT($AB4,2))),DATE(VALUE(RIGHT($AB4,4)),VALUE(MID($AB4,4,2)),VALUE(LEFT($AB4,2))))) -> 45313 | C4: =YEAR($B4) -> 2024 | D4: ="Q"&ROUNDUP(MONTH($B4)/3,0) -> Q1 | E4: =MONTH($B4) -> 1 | F4: =INDEX(Parametros!$I$5:$I$16,$E4) -> Ene | G4: =TEXT($C4,"0000")&"-"&TEXT($E4,"00") -> 2024-01 | H4: =INDEX(Parametros!$C$71:$C$91,MATCH(TRIM(INDEX(Datos_Origen!$C$2:$C$2459,$Z4)),Parametros!$B$71:$B$91,0)) -> AMBA | I4: =IF(TRIM($AD4)="",INDEX(Parametros!$I$20:$I$24,MATCH($H4,Parametros!$H$20:$H$24,0)),TRIM($AD4)) -> Buenos Aires | J4: =INDEX(Parametros!$C$95:$C$106,MATCH(TRIM(INDEX(Datos_Origen!$E$2:$E$2459,$Z4)),Parametros!$B$95:$B$106,0)) -> Tienda fisica | K4: =INDEX(Parametros!$C$48:$C$67,MATCH(TRIM(INDEX(Datos_Origen!$F$2:$F$2459,$Z4)),Parametros!$B$48:$B$67,0)) -> Computacion | L4: =$K4&" "&$C4 -> Computacion 2024 | M4: =TRIM(INDEX(Datos_Origen!$G$2:$G$2459,$Z4)) -> Monitor 4K 27 | N4: =$M4&" "&$C4 -> Monitor 4K 27 2024 | O4: =IF(ISTEXT($AC4),VALUE($AC4),$AC4) -> 18 | P4: =INDEX(Datos_Origen!$I$2:$I$2459,$Z4) -> 441 | Q4: =INDEX(Datos_Origen!$J$2:$J$2459,$Z4) -> 272.25 | R4: =ROUND($O4*$P4,2) -> 7938 | S4: =ROUND($O4*$Q4,2) -> 4900.5 | T4: =ROUND($R4*SUMIFS(Parametros!$E$28:$E$43,Parametros!$B$28:$B$43,$J4,Parametros!$C$28:$C$43,$C4,Parametros!$D$28:$D$43,$D4),2) -> 95.26 | U4: =$R4-$S4-$T4 -> 2942.24 | V4: =IFERROR($U4/$R4,0) -> 0.37065256 | W4: =IF(AND($V4>=Parametros!$C$8,$R4>=Parametros!$C$12),"Alta rentabilidad",IF(OR($V4<Parametros!$C$11,$R4<Parametros!$C$13),"Revisar","Estandar")) -> Alta rentabilidad | X4: =IF(AND($J4="E-commerce",IFERROR($T4/$R4,0)>Parametros!$C$14),"Alerta","OK") -> OK | Y4: =IF($R4>=Parametros!$C$12,"Alto",IF($R4<Parametros!$C$13,"Bajo","Medio")) -> Alto | Z4: 1921 | AA4: =IF(MATCH($A4,Datos_Origen!$A$2:$A$2459,0)=$Z4,"OK","REVISAR") -> OK | AB4: =INDEX(Datos_Origen!$B$2:$B$2459,$Z4) -> 2024-01-22 | AC4: =INDEX(Datos_Origen!$H$2:$H$2459,$Z4) -> 18 | AD4: =INDEX(Datos_Origen!$D$2:$D$2459,$Z4)&""
A5: =INDEX(Datos_Origen!$A$2:$A$2459,$Z5) -> 4 | B5: =IF(ISNUMBER($AB5),$AB5,IF(MID($AB5,5,1)="-",DATE(VALUE(LEFT($AB5,4)),VALUE(MID($AB5,6,2)),VALUE(RIGHT($AB5,2))),DATE(VALUE(RIGHT($AB5,4)),VALUE(MID($AB5,4,2)),VALUE(LEFT($AB5,2))))) -> 45293 | C5: =YEAR($B5) -> 2024 | D5: ="Q"&ROUNDUP(MONTH($B5)/3,0) -> Q1 | E5: =MONTH($B5) -> 1 | F5: =INDEX(Parametros!$I$5:$I$16,$E5) -> Ene | G5: =TEXT($C5,"0000")&"-"&TEXT($E5,"00") -> 2024-01 | H5: =INDEX(Parametros!$C$71:$C$91,MATCH(TRIM(INDEX(Datos_Origen!$C$2:$C$2459,$Z5)),Parametros!$B$71:$B$91,0)) -> AMBA | I5: =IF(TRIM($AD5)="",INDEX(Parametros!$I$20:$I$24,MATCH($H5,Parametros!$H$20:$H$24,0)),TRIM($AD5)) -> Buenos Aires | J5: =INDEX(Parametros!$C$95:$C$106,MATCH(TRIM(INDEX(Datos_Origen!$E$2:$E$2459,$Z5)),Parametros!$B$95:$B$106,0)) -> E-commerce | K5: =INDEX(Parametros!$C$48:$C$67,MATCH(TRIM(INDEX(Datos_Origen!$F$2:$F$2459,$Z5)),Parametros!$B$48:$B$67,0)) -> Computacion | L5: =$K5&" "&$C5 -> Computacion 2024 | M5: =TRIM(INDEX(Datos_Origen!$G$2:$G$2459,$Z5)) -> Monitor 4K 27 | N5: =$M5&" "&$C5 -> Monitor 4K 27 2024 | O5: =IF(ISTEXT($AC5),VALUE($AC5),$AC5) -> 8 | P5: =INDEX(Datos_Origen!$I$2:$I$2459,$Z5) -> 441 | Q5: =INDEX(Datos_Origen!$J$2:$J$2459,$Z5) -> 272.25 | R5: =ROUND($O5*$P5,2) -> 3528 | S5: =ROUND($O5*$Q5,2) -> 2178 | T5: =ROUND($R5*SUMIFS(Parametros!$E$28:$E$43,Parametros!$B$28:$B$43,$J5,Parametros!$C$28:$C$43,$C5,Parametros!$D$28:$D$43,$D5),2) -> 148.18 | U5: =$R5-$S5-$T5 -> 1201.82 | V5: =IFERROR($U5/$R5,0) -> 0.34065193 | W5: =IF(AND($V5>=Parametros!$C$8,$R5>=Parametros!$C$12),"Alta rentabilidad",IF(OR($V5<Parametros!$C$11,$R5<Parametros!$C$13),"Revisar","Estandar")) -> Alta rentabilidad | X5: =IF(AND($J5="E-commerce",IFERROR($T5/$R5,0)>Parametros!$C$14),"Alerta","OK") -> OK | Y5: =IF($R5>=Parametros!$C$12,"Alto",IF($R5<Parametros!$C$13,"Bajo","Medio")) -> Alto | Z5: 2435 | AA5: =IF(MATCH($A5,Datos_Origen!$A$2:$A$2459,0)=$Z5,"OK","REVISAR") -> OK | AB5: =INDEX(Datos_Origen!$B$2:$B$2459,$Z5) -> 45293 | AC5: =INDEX(Datos_Origen!$H$2:$H$2459,$Z5) -> 8 | AD5: =INDEX(Datos_Origen!$D$2:$D$2459,$Z5)&"" -> Buenos Aires
A6: =INDEX(Datos_Origen!$A$2:$A$2459,$Z6) -> 5 | B6: =IF(ISNUMBER($AB6),$AB6,IF(MID($AB6,5,1)="-",DATE(VALUE(LEFT($AB6,4)),VALUE(MID($AB6,6,2)),VALUE(RIGHT($AB6,2))),DATE(VALUE(RIGHT($AB6,4)),VALUE(MID($AB6,4,2)),VALUE(LEFT($AB6,2))))) -> 45300 | C6: =YEAR($B6) -> 2024 | D6: ="Q"&ROUNDUP(MONTH($B6)/3,0) -> Q1 | E6: =MONTH($B6) -> 1 | F6: =INDEX(Parametros!$I$5:$I$16,$E6) -> Ene | G6: =TEXT($C6,"0000")&"-"&TEXT($E6,"00") -> 2024-01 | H6: =INDEX(Parametros!$C$71:$C$91,MATCH(TRIM(INDEX(Datos_Origen!$C$2:$C$2459,$Z6)),Parametros!$B$71:$B$91,0)) -> AMBA | I6: =IF(TRIM($AD6)="",INDEX(Parametros!$I$20:$I$24,MATCH($H6,Parametros!$H$20:$H$24,0)),TRIM($AD6)) -> Buenos Aires | J6: =INDEX(Parametros!$C$95:$C$106,MATCH(TRIM(INDEX(Datos_Origen!$E$2:$E$2459,$Z6)),Parametros!$B$95:$B$106,0)) -> Tienda fisica | K6: =INDEX(Parametros!$C$48:$C$67,MATCH(TRIM(INDEX(Datos_Origen!$F$2:$F$2459,$Z6)),Parametros!$B$48:$B$67,0)) -> Computacion | L6: =$K6&" "&$C6 -> Computacion 2024 | M6: =TRIM(INDEX(Datos_Origen!$G$2:$G$2459,$Z6)) -> PC Gamer Ryzen | N6: =$M6&" "&$C6 -> PC Gamer Ryzen 2024 | O6: =IF(ISTEXT($AC6),VALUE($AC6),$AC6) -> 19 | P6: =INDEX(Datos_Origen!$I$2:$I$2459,$Z6) -> 1617 | Q6: =INDEX(Datos_Origen!$J$2:$J$2459,$Z6) -> 1122 | R6: =ROUND($O6*$P6,2) -> 30723 | S6: =ROUND($O6*$Q6,2) -> 21318 | T6: =ROUND($R6*SUMIFS(Parametros!$E$28:$E$43,Parametros!$B$28:$B$43,$J6,Parametros!$C$28:$C$43,$C6,Parametros!$D$28:$D$43,$D6),2) -> 368.68 | U6: =$R6-$S6-$T6 -> 9036.32 | V6: =IFERROR($U6/$R6,0) -> 0.29412232 | W6: =IF(AND($V6>=Parametros!$C$8,$R6>=Parametros!$C$12),"Alta rentabilidad",IF(OR($V6<Parametros!$C$11,$R6<Parametros!$C$13),"Revisar","Estandar")) -> Estandar | X6: =IF(AND($J6="E-commerce",IFERROR($T6/$R6,0)>Parametros!$C$14),"Alerta","OK") -> OK | Y6: =IF($R6>=Parametros!$C$12,"Alto",IF($R6<Parametros!$C$13,"Bajo","Medio")) -> Alto | Z6: 242 | AA6: =IF(MATCH($A6,Datos_Origen!$A$2:$A$2459,0)=$Z6,"OK","REVISAR") -> OK | AB6: =INDEX(Datos_Origen!$B$2:$B$2459,$Z6) -> 45300 | AC6: =INDEX(Datos_Origen!$H$2:$H$2459,$Z6) -> 19 | AD6: =INDEX(Datos_Origen!$D$2:$D$2459,$Z6)&"" -> Buenos Aires
A7: =INDEX(Datos_Origen!$A$2:$A$2459,$Z7) -> 6 | B7: =IF(ISNUMBER($AB7),$AB7,IF(MID($AB7,5,1)="-",DATE(VALUE(LEFT($AB7,4)),VALUE(MID($AB7,6,2)),VALUE(RIGHT($AB7,2))),DATE(VALUE(RIGHT($AB7,4)),VALUE(MID($AB7,4,2)),VALUE(LEFT($AB7,2))))) -> 45307 | C7: =YEAR($B7) -> 2024 | D7: ="Q"&ROUNDUP(MONTH($B7)/3,0) -> Q1 | E7: =MONTH($B7) -> 1 | F7: =INDEX(Parametros!$I$5:$I$16,$E7) -> Ene | G7: =TEXT($C7,"0000")&"-"&TEXT($E7,"00") -> 2024-01 | H7: =INDEX(Parametros!$C$71:$C$91,MATCH(TRIM(INDEX(Datos_Origen!$C$2:$C$2459,$Z7)),Parametros!$B$71:$B$91,0)) -> AMBA | I7: =IF(TRIM($AD7)="",INDEX(Parametros!$I$20:$I$24,MATCH($H7,Parametros!$H$20:$H$24,0)),TRIM($AD7)) -> Buenos Aires | J7: =INDEX(Parametros!$C$95:$C$106,MATCH(TRIM(INDEX(Datos_Origen!$E$2:$E$2459,$Z7)),Parametros!$B$95:$B$106,0)) -> E-commerce | K7: =INDEX(Parametros!$C$48:$C$67,MATCH(TRIM(INDEX(Datos_Origen!$F$2:$F$2459,$Z7)),Parametros!$B$48:$B$67,0)) -> Computacion | L7: =$K7&" "&$C7 -> Computacion 2024 | M7: =TRIM(INDEX(Datos_Origen!$G$2:$G$2459,$Z7)) -> PC Gamer Ryzen | N7: =$M7&" "&$C7 -> PC Gamer Ryzen 2024 | O7: =IF(ISTEXT($AC7),VALUE($AC7),$AC7) -> 8 | P7: =INDEX(Datos_Origen!$I$2:$I$2459,$Z7) -> 1617 | Q7: =INDEX(Datos_Origen!$J$2:$J$2459,$Z7) -> 1122 | R7: =ROUND($O7*$P7,2) -> 12936 | S7: =ROUND($O7*$Q7,2) -> 8976 | T7: =ROUND($R7*SUMIFS(Parametros!$E$28:$E$43,Parametros!$B$28:$B$43,$J7,Parametros!$C$28:$C$43,$C7,Parametros!$D$28:$D$43,$D7),2) -> 543.31 | U7: =$R7-$S7-$T7 -> 3416.69 | V7: =IFERROR($U7/$R7,0) -> 0.2641226 | W7: =IF(AND($V7>=Parametros!$C$8,$R7>=Parametros!$C$12),"Alta rentabilidad",IF(OR($V7<Parametros!$C$11,$R7<Parametros!$C$13),"Revisar","Estandar")) -> Revisar | X7: =IF(AND($J7="E-commerce",IFERROR($T7/$R7,0)>Parametros!$C$14),"Alerta","OK") -> OK | Y7: =IF($R7>=Parametros!$C$12,"Alto",IF($R7<Parametros!$C$13,"Bajo","Medio")) -> Alto | Z7: 134 | AA7: =IF(MATCH($A7,Datos_Origen!$A$2:$A$2459,0)=$Z7,"OK","REVISAR") -> OK | AB7: =INDEX(Datos_Origen!$B$2:$B$2459,$Z7) -> 45307 | AC7: =INDEX(Datos_Origen!$H$2:$H$2459,$Z7) -> 8 | AD7: =INDEX(Datos_Origen!$D$2:$D$2459,$Z7)&"" -> Buenos Aires
A8: =INDEX(Datos_Origen!$A$2:$A$2459,$Z8) -> 7 | B8: =IF(ISNUMBER($AB8),$AB8,IF(MID($AB8,5,1)="-",DATE(VALUE(LEFT($AB8,4)),VALUE(MID($AB8,6,2)),VALUE(RIGHT($AB8,2))),DATE(VALUE(RIGHT($AB8,4)),VALUE(MID($AB8,4,2)),VALUE(LEFT($AB8,2))))) -> 45314 | C8: =YEAR($B8) -> 2024 | D8: ="Q"&ROUNDUP(MONTH($B8)/3,0) -> Q1 | E8: =MONTH($B8) -> 1 | F8: =INDEX(Parametros!$I$5:$I$16,$E8) -> Ene | G8: =TEXT($C8,"0000")&"-"&TEXT($E8,"00") -> 2024-01 | H8: =INDEX(Parametros!$C$71:$C$91,MATCH(TRIM(INDEX(Datos_Origen!$C$2:$C$2459,$Z8)),Parametros!$B$71:$B$91,0)) -> AMBA | I8: =IF(TRIM($AD8)="",INDEX(Parametros!$I$20:$I$24,MATCH($H8,Parametros!$H$20:$H$24,0)),TRIM($AD8)) -> Buenos Aires | J8: =INDEX(Parametros!$C$95:$C$106,MATCH(TRIM(INDEX(Datos_Origen!$E$2:$E$2459,$Z8)),Parametros!$B$95:$B$106,0)) -> Tienda fisica | K8: =INDEX(Parametros!$C$48:$C$67,MATCH(TRIM(INDEX(Datos_Origen!$F$2:$F$2459,$Z8)),Parametros!$B$48:$B$67,0)) -> Accesorios | L8: =$K8&" "&$C8 -> Accesorios 2024 | M8: =TRIM(INDEX(Datos_Origen!$G$2:$G$2459,$Z8)) -> Mouse Inalambrico | N8: =$M8&" "&$C8 -> Mouse Inalambrico 2024 | O8: =IF(ISTEXT($AC8),VALUE($AC8),$AC8) -> 91 | P8: =INDEX(Datos_Origen!$I$2:$I$2459,$Z8) -> 27.44 | Q8: =INDEX(Datos_Origen!$J$2:$J$2459,$Z8) -> 13.44 | R8: =ROUND($O8*$P8,2) -> 2497.04 | S8: =ROUND($O8*$Q8,2) -> 1223.04 | T8: =ROUND($R8*SUMIFS(Parametros!$E$28:$E$43,Parametros!$B$28:$B$43,$J8,Parametros!$C$28:$C$43,$C8,Parametros!$D$28:$D$43,$D8),2) -> 29.96 | U8: =$R8-$S8-$T8 -> 1244.04 | V8: =IFERROR($U8/$R8,0) -> 0.49820588 | W8: =IF(AND($V8>=Parametros!$C$8,$R8>=Parametros!$C$12),"Alta rentabilidad",IF(OR($V8<Parametros!$C$11,$R8<Parametros!$C$13),"Revisar","Estandar")) -> Estandar | X8: =IF(AND($J8="E-commerce",IFERROR($T8/$R8,0)>Parametros!$C$14),"Alerta","OK") -> OK | Y8: =IF($R8>=Parametros!$C$12,"Alto",IF($R8<Parametros!$C$13,"Bajo","Medio")) -> Medio | Z8: 1285 | AA8: =IF(MATCH($A8,Datos_Origen!$A$2:$A$2459,0)=$Z8,"OK","REVISAR") -> OK | AB8: =INDEX(Datos_Origen!$B$2:$B$2459,$Z8) -> 45314 | AC8: =INDEX(Datos_Origen!$H$2:$H$2459,$Z8) -> 91 | AD8: =INDEX(Datos_Origen!$D$2:$D$2459,$Z8)&"" -> Buenos Aires
A9: =INDEX(Datos_Origen!$A$2:$A$2459,$Z9) -> 8 | B9: =IF(ISNUMBER($AB9),$AB9,IF(MID($AB9,5,1)="-",DATE(VALUE(LEFT($AB9,4)),VALUE(MID($AB9,6,2)),VALUE(RIGHT($AB9,2))),DATE(VALUE(RIGHT($AB9,4)),VALUE(MID($AB9,4,2)),VALUE(LEFT($AB9,2))))) -> 45294 | C9: =YEAR($B9) -> 2024 | D9: ="Q"&ROUNDUP(MONTH($B9)/3,0) -> Q1 | E9: =MONTH($B9) -> 1 | F9: =INDEX(Parametros!$I$5:$I$16,$E9) -> Ene | G9: =TEXT($C9,"0000")&"-"&TEXT($E9,"00") -> 2024-01 | H9: =INDEX(Parametros!$C$71:$C$91,MATCH(TRIM(INDEX(Datos_Origen!$C$2:$C$2459,$Z9)),Parametros!$B$71:$B$91,0)) -> AMBA | I9: =IF(TRIM($AD9)="",INDEX(Parametros!$I$20:$I$24,MATCH($H9,Parametros!$H$20:$H$24,0)),TRIM($AD9)) -> Buenos Aires | J9: =INDEX(Parametros!$C$95:$C$106,MATCH(TRIM(INDEX(Datos_Origen!$E$2:$E$2459,$Z9)),Parametros!$B$95:$B$106,0)) -> E-commerce | K9: =INDEX(Parametros!$C$48:$C$67,MATCH(TRIM(INDEX(Datos_Origen!$F$2:$F$2459,$Z9)),Parametros!$B$48:$B$67,0)) -> Accesorios | L9: =$K9&" "&$C9 -> Accesorios 2024 | M9: =TRIM(INDEX(Datos_Origen!$G$2:$G$2459,$Z9)) -> Mouse Inalambrico | N9: =$M9&" "&$C9 -> Mouse Inalambrico 2024 | O9: =IF(ISTEXT($AC9),VALUE($AC9),$AC9) -> 30 | P9: =INDEX(Datos_Origen!$I$2:$I$2459,$Z9) -> 27.44 | Q9: =INDEX(Datos_Origen!$J$2:$J$2459,$Z9) -> 13.44 | R9: =ROUND($O9*$P9,2) -> 823.2 | S9: =ROUND($O9*$Q9,2) -> 403.2 | T9: =ROUND($R9*SUMIFS(Parametros!$E$28:$E$43,Parametros!$B$28:$B$43,$J9,Parametros!$C$28:$C$43,$C9,Parametros!$D$28:$D$43,$D9),2) -> 34.57 | U9: =$R9-$S9-$T9 -> 385.43 | V9: =IFERROR($U9/$R9,0) -> 0.46820943 | W9: =IF(AND($V9>=Parametros!$C$8,$R9>=Parametros!$C$12),"Alta rentabilidad",IF(OR($V9<Parametros!$C$11,$R9<Parametros!$C$13),"Revisar","Estandar")) -> Estandar | X9: =IF(AND($J9="E-commerce",IFERROR($T9/$R9,0)>Parametros!$C$14),"Alerta","OK") -> OK | Y9: =IF($R9>=Parametros!$C$12,"Alto",IF($R9<Parametros!$C$13,"Bajo","Medio")) -> Medio | Z9: 3 | AA9: =IF(MATCH($A9,Datos_Origen!$A$2:$A$2459,0)=$Z9,"OK","REVISAR") -> OK | AB9: =INDEX(Datos_Origen!$B$2:$B$2459,$Z9) -> 03/01/2024 | AC9: =INDEX(Datos_Origen!$H$2:$H$2459,$Z9) -> 30 | AD9: =INDEX(Datos_Origen!$D$2:$D$2459,$Z9)&"" -> Buenos Aires
A10: =INDEX(Datos_Origen!$A$2:$A$2459,$Z10) -> 9 | B10: =IF(ISNUMBER($AB10),$AB10,IF(MID($AB10,5,1)="-",DATE(VALUE(LEFT($AB10,4)),VALUE(MID($AB10,6,2)),VALUE(RIGHT($AB10,2))),DATE(VALUE(RIGHT($AB10,4)),VALUE(MID($AB10,4,2)),VALUE(LEFT($AB10,2))))) -> 45301 | C10: =YEAR($B10) -> 2024 | D10: ="Q"&ROUNDUP(MONTH($B10)/3,0) -> Q1 | E10: =MONTH($B10) -> 1 | F10: =INDEX(Parametros!$I$5:$I$16,$E10) -> Ene | G10: =TEXT($C10,"0000")&"-"&TEXT($E10,"00") -> 2024-01 | H10: =INDEX(Parametros!$C$71:$C$91,MATCH(TRIM(INDEX(Datos_Origen!$C$2:$C$2459,$Z10)),Parametros!$B$71:$B$91,0)) -> AMBA | I10: =IF(TRIM($AD10)="",INDEX(Parametros!$I$20:$I$24,MATCH($H10,Parametros!$H$20:$H$24,0)),TRIM($AD10)) -> Buenos Aires | J10: =INDEX(Parametros!$C$95:$C$106,MATCH(TRIM(INDEX(Datos_Origen!$E$2:$E$2459,$Z10)),Parametros!$B$95:$B$106,0)) -> Tienda fisica | K10: =INDEX(Parametros!$C$48:$C$67,MATCH(TRIM(INDEX(Datos_Origen!$F$2:$F$2459,$Z10)),Parametros!$B$48:$B$67,0)) -> Accesorios | L10: =$K10&" "&$C10 -> Accesorios 2024 | M10: =TRIM(INDEX(Datos_Origen!$G$2:$G$2459,$Z10)) -> Teclado Mecanico | N10: =$M10&" "&$C10 -> Teclado Mecanico 2024 | O10: =IF(ISTEXT($AC10),VALUE($AC10),$AC10) -> 95 | P10: =INDEX(Datos_Origen!$I$2:$I$2459,$Z10) -> 93.1 | Q10: =INDEX(Datos_Origen!$J$2:$J$2459,$Z10) -> 47.98 | R10: =ROUND($O10*$P10,2) -> 8844.5 | S10: =ROUND($O10*$Q10,2) -> 4558.1 | T10: =ROUND($R10*SUMIFS(Parametros!$E$28:$E$43,Parametros!$B$28:$B$43,$J10,Parametros!$C$28:$C$43,$C10,Parametros!$D$28:$D$43,$D10),2) -> 106.13 | U10: =$R10-$S10-$T10 -> 4180.27 | V10: =IFERROR($U10/$R10,0) -> 0.47264062 | W10: =IF(AND($V10>=Parametros!$C$8,$R10>=Parametros!$C$12),"Alta rentabilidad",IF(OR($V10<Parametros!$C$11,$R10<Parametros!$C$13),"Revisar","Estandar")) -> Alta rentabilidad | X10: =IF(AND($J10="E-commerce",IFERROR($T10/$R10,0)>Parametros!$C$14),"Alerta","OK") -> OK | Y10: =IF($R10>=Parametros!$C$12,"Alto",IF($R10<Parametros!$C$13,"Bajo","Medio")) -> Alto | Z10: 1967 | AA10: =IF(MATCH($A10,Datos_Origen!$A$2:$A$2459,0)=$Z10,"OK","REVISAR") -> OK | AB10: =INDEX(Datos_Origen!$B$2:$B$2459,$Z10) -> 2024-01-10 | AC10: =INDEX(Datos_Origen!$H$2:$H$2459,$Z10) -> 95 | AD10: =INDEX(Datos_Origen!$D$2:$D$2459,$Z10)&"" -> Buenos Aires
A11: =INDEX(Datos_Origen!$A$2:$A$2459,$Z11) -> 10 | B11: =IF(ISNUMBER($AB11),$AB11,IF(MID($AB11,5,1)="-",DATE(VALUE(LEFT($AB11,4)),VALUE(MID($AB11,6,2)),VALUE(RIGHT($AB11,2))),DATE(VALUE(RIGHT($AB11,4)),VALUE(MID($AB11,4,2)),VALUE(LEFT($AB11,2))))) -> 45308 | C11: =YEAR($B11) -> 2024 | D11: ="Q"&ROUNDUP(MONTH($B11)/3,0) -> Q1 | E11: =MONTH($B11) -> 1 | F11: =INDEX(Parametros!$I$5:$I$16,$E11) -> Ene | G11: =TEXT($C11,"0000")&"-"&TEXT($E11,"00") -> 2024-01 | H11: =INDEX(Parametros!$C$71:$C$91,MATCH(TRIM(INDEX(Datos_Origen!$C$2:$C$2459,$Z11)),Parametros!$B$71:$B$91,0)) -> AMBA | I11: =IF(TRIM($AD11)="",INDEX(Parametros!$I$20:$I$24,MATCH($H11,Parametros!$H$20:$H$24,0)),TRIM($AD11)) -> Buenos Aires | J11: =INDEX(Parametros!$C$95:$C$106,MATCH(TRIM(INDEX(Datos_Origen!$E$2:$E$2459,$Z11)),Parametros!$B$95:$B$106,0)) -> E-commerce | K11: =INDEX(Parametros!$C$48:$C$67,MATCH(TRIM(INDEX(Datos_Origen!$F$2:$F$2459,$Z11)),Parametros!$B$48:$B$67,0)) -> Accesorios | L11: =$K11&" "&$C11 -> Accesorios 2024 | M11: =TRIM(INDEX(Datos_Origen!$G$2:$G$2459,$Z11)) -> Teclado Mecanico | N11: =$M11&" "&$C11 -> Teclado Mecanico 2024 | O11: =IF(ISTEXT($AC11),VALUE($AC11),$AC11) -> 35 | P11: =INDEX(Datos_Origen!$I$2:$I$2459,$Z11) -> 93.1 | Q11: =INDEX(Datos_Origen!$J$2:$J$2459,$Z11) -> 47.98 | R11: =ROUND($O11*$P11,2) -> 3258.5 | S11: =ROUND($O11*$Q11,2) -> 1679.3 | T11: =ROUND($R11*SUMIFS(Parametros!$E$28:$E$43,Parametros!$B$28:$B$43,$J11,Parametros!$C$28:$C$43,$C11,Parametros!$D$28:$D$43,$D11),2) -> 136.86 | U11: =$R11-$S11-$T11 -> 1442.34 | V11: =IFERROR($U11/$R11,0) -> 0.44263925 | W11: =IF(AND($V11>=Parametros!$C$8,$R11>=Parametros!$C$12),"Alta rentabilidad",IF(OR($V11<Parametros!$C$11,$R11<Parametros!$C$13),"Revisar","Estandar")) -> Alta rentabilidad | X11: =IF(AND($J11="E-commerce",IFERROR($T11/$R11,0)>Parametros!$C$14),"Alerta","OK") -> OK | Y11: =IF($R11>=Parametros!$C$12,"Alto",IF($R11<Parametros!$C$13,"Bajo","Medio")) -> Alto | Z11: 1971 | AA11: =IF(MATCH($A11,Datos_Origen!$A$2:$A$2459,0)=$Z11,"OK","REVISAR") -> OK | AB11: =INDEX(Datos_Origen!$B$2:$B$2459,$Z11) -> 45308 | AC11: =INDEX(Datos_Origen!$H$2:$H$2459,$Z11) -> 35 | AD11: =INDEX(Datos_Origen!$D$2:$D$2459,$Z11)&"" -> Buenos Aires
A12: =INDEX(Datos_Origen!$A$2:$A$2459,$Z12) -> 11 | B12: =IF(ISNUMBER($AB12),$AB12,IF(MID($AB12,5,1)="-",DATE(VALUE(LEFT($AB12,4)),VALUE(MID($AB12,6,2)),VALUE(RIGHT($AB12,2))),DATE(VALUE(RIGHT($AB12,4)),VALUE(MID($AB12,4,2)),VALUE(LEFT($AB12,2))))) -> 45315 | C12: =YEAR($B12) -> 2024 | D12: ="Q"&ROUNDUP(MONTH($B12)/3,0) -> Q1 | E12: =MONTH($B12) -> 1 | F12: =INDEX(Parametros!$I$5:$I$16,$E12) -> Ene | G12: =TEXT($C12,"0000")&"-"&TEXT($E12,"00") -> 2024-01 | H12: =INDEX(Parametros!$C$71:$C$91,MATCH(TRIM(INDEX(Datos_Origen!$C$2:$C$2459,$Z12)),Parametros!$B$71:$B$91,0)) -> AMBA | I12: =IF(TRIM($AD12)="",INDEX(Parametros!$I$20:$I$24,MATCH($H12,Parametros!$H$20:$H$24,0)),TRIM($AD12)) -> Buenos Aires | J12: =INDEX(Parametros!$C$95:$C$106,MATCH(TRIM(INDEX(Datos_Origen!$E$2:$E$2459,$Z12)),Parametros!$B$95:$B$106,0)) -> Tienda fisica | K12: =INDEX(Parametros!$C$48:$C$67,MATCH(TRIM(INDEX(Datos_Origen!$F$2:$F$2459,$Z12)),Parametros!$B$48:$B$67,0)) -> Accesorios | L12: =$K12&" "&$C12 -> Accesorios 2024 | M12: =TRIM(INDEX(Datos_Origen!$G$2:$G$2459,$Z12)) -> Webcam Full HD | N12: =$M12&" "&$C12 -> Webcam Full HD 2024 | O12: =IF(ISTEXT($AC12),VALUE($AC12),$AC12) -> 98 | P12: =INDEX(Datos_Origen!$I$2:$I$2459,$Z12) -> 63.7 | Q12: =INDEX(Datos_Origen!$J$2:$J$2459,$Z12) -> 35.43 | R12: =ROUND($O12*$P12,2) -> 6242.6 | S12: =ROUND($O12*$Q12,2) -> 3472.14 | T12: =ROUND($R12*SUMIFS(Parametros!$E$28:$E$43,Parametros!$B$28:$B$43,$J12,Parametros!$C$28:$C$43,$C12,Parametros!$D$28:$D$43,$D12),2) -> 74.91 | U12: =$R12-$S12-$T12 -> 2695.55 | V12: =IFERROR($U12/$R12,0) -> 0.43179925 | W12: =IF(AND($V12>=Parametros!$C$8,$R12>=Parametros!$C$12),"Alta rentabilidad",IF(OR($V12<Parametros!$C$11,$R12<Parametros!$C$13),"Revisar","Estandar")) -> Alta rentabilidad | X12: =IF(AND($J12="E-commerce",IFERROR($T12/$R12,0)>Parametros!$C$14),"Alerta","OK") -> OK | Y12: =IF($R12>=Parametros!$C$12,"Alto",IF($R12<Parametros!$C$13,"Bajo","Medio")) -> Alto | Z12: 1546 | AA12: =IF(MATCH($A12,Datos_Origen!$A$2:$A$2459,0)=$Z12,"OK","REVISAR") -> OK | AB12: =INDEX(Datos_Origen!$B$2:$B$2459,$Z12) -> 45315 | AC12: =INDEX(Datos_Origen!$H$2:$H$2459,$Z12) -> 98 | AD12: =INDEX(Datos_Origen!$D$2:$D$2459,$Z12)&"" -> Buenos Aires
A13: =INDEX(Datos_Origen!$A$2:$A$2459,$Z13) -> 12 | B13: =IF(ISNUMBER($AB13),$AB13,IF(MID($AB13,5,1)="-",DATE(VALUE(LEFT($AB13,4)),VALUE(MID($AB13,6,2)),VALUE(RIGHT($AB13,2))),DATE(VALUE(RIGHT($AB13,4)),VALUE(MID($AB13,4,2)),VALUE(LEFT($AB13,2))))) -> 45295 | C13: =YEAR($B13) -> 2024 | D13: ="Q"&ROUNDUP(MONTH($B13)/3,0) -> Q1 | E13: =MONTH($B13) -> 1 | F13: =INDEX(Parametros!$I$5:$I$16,$E13) -> Ene | G13: =TEXT($C13,"0000")&"-"&TEXT($E13,"00") -> 2024-01 | H13: =INDEX(Parametros!$C$71:$C$91,MATCH(TRIM(INDEX(Datos_Origen!$C$2:$C$2459,$Z13)),Parametros!$B$71:$B$91,0)) -> AMBA | I13: =IF(TRIM($AD13)="",INDEX(Parametros!$I$20:$I$24,MATCH($H13,Parametros!$H$20:$H$24,0)),TRIM($AD13)) -> Buenos Aires | J13: =INDEX(Parametros!$C$95:$C$106,MATCH(TRIM(INDEX(Datos_Origen!$E$2:$E$2459,$Z13)),Parametros!$B$95:$B$106,0)) -> E-commerce | K13: =INDEX(Parametros!$C$48:$C$67,MATCH(TRIM(INDEX(Datos_Origen!$F$2:$F$2459,$Z13)),Parametros!$B$48:$B$67,0)) -> Accesorios | L13: =$K13&" "&$C13 -> Accesorios 2024 | M13: =TRIM(INDEX(Datos_Origen!$G$2:$G$2459,$Z13)) -> Webcam Full HD | N13: =$M13&" "&$C13 -> Webcam Full HD 2024 | O13: =IF(ISTEXT($AC13),VALUE($AC13),$AC13) -> 32 | P13: =INDEX(Datos_Origen!$I$2:$I$2459,$Z13) -> 63.7 | Q13: =INDEX(Datos_Origen!$J$2:$J$2459,$Z13) -> 35.43 | R13: =ROUND($O13*$P13,2) -> 2038.4 | S13: =ROUND($O13*$Q13,2) -> 1133.76 | T13: =ROUND($R13*SUMIFS(Parametros!$E$28:$E$43,Parametros!$B$28:$B$43,$J13,Parametros!$C$28:$C$43,$C13,Parametros!$D$28:$D$43,$D13),2) -> 85.61 | U13: =$R13-$S13-$T13 -> 819.03 | V13: =IFERROR($U13/$R13,0) -> 0.40180043 | W13: =IF(AND($V13>=Parametros!$C$8,$R13>=Parametros!$C$12),"Alta rentabilidad",IF(OR($V13<Parametros!$C$11,$R13<Parametros!$C$13),"Revisar","Estandar")) -> Estandar | X13: =IF(AND($J13="E-commerce",IFERROR($T13/$R13,0)>Parametros!$C$14),"Alerta","OK") -> OK | Y13: =IF($R13>=Parametros!$C$12,"Alto",IF($R13<Parametros!$C$13,"Bajo","Medio")) -> Medio | Z13: 303 | AA13: =IF(MATCH($A13,Datos_Origen!$A$2:$A$2459,0)=$Z13,"OK","REVISAR") -> OK | AB13: =INDEX(Datos_Origen!$B$2:$B$2459,$Z13) -> 45295 | AC13: =INDEX(Datos_Origen!$H$2:$H$2459,$Z13) -> 32 | AD13: =INDEX(Datos_Origen!$D$2:$D$2459,$Z13)&"" -> Buenos Aires
... A2401: =INDEX(Datos_Origen!$A$2:$A$2459,$Z2401) -> 2400 | B2401: =IF(ISNUMBER($AB2401),$AB2401,IF(MID($AB2401,5,1)="-",DATE(VALUE(LEFT($AB2401,4)),VALUE(MID($AB2401,6,2)),VALUE(RIGHT($AB2401,2))),DATE(VALUE(RIGHT($AB2401,4)),VALUE(MID($AB2401,4,2)),VALUE(LEFT($AB2401,2))))) -> 45998 | C2401: =YEAR($B2401) -> 2025 | D2401: ="Q"&ROUNDUP(MONTH($B2401)/3,0) -> Q4 | E2401: =MONTH($B2401) -> 12 | F2401: =INDEX(Parametros!$I$5:$I$16,$E2401) -> Dic | G2401: =TEXT($C2401,"0000")&"-"&TEXT($E2401,"00") -> 2025-12 | H2401: =INDEX(Parametros!$C$71:$C$91,MATCH(TRIM(INDEX(Datos_Origen!$C$2:$C$2459,$Z2401)),Parametros!$B$71:$B$91,0)) -> NOA | I2401: =IF(TRIM($AD2401)="",INDEX(Parametros!$I$20:$I$24,MATCH($H2401,Parametros!$H$20:$H$24,0)),TRIM($AD2401)) -> Tucuman | J2401: =INDEX(Parametros!$C$95:$C$106,MATCH(TRIM(INDEX(Datos_Origen!$E$2:$E$2459,$Z2401)),Parametros!$B$95:$B$106,0)) -> E-commerce | K2401: =INDEX(Parametros!$C$48:$C$67,MATCH(TRIM(INDEX(Datos_Origen!$F$2:$F$2459,$Z2401)),Parametros!$B$48:$B$67,0)) -> Almacenamiento | L2401: =$K2401&" "&$C2401 -> Almacenamiento 2025 | M2401: =TRIM(INDEX(Datos_Origen!$G$2:$G$2459,$Z2401)) -> Pendrive 256GB | N2401: =$M2401&" "&$C2401 -> Pendrive 256GB 2025 | O2401: =IF(ISTEXT($AC2401),VALUE($AC2401),$AC2401) -> 17 | P2401: =INDEX(Datos_Origen!$I$2:$I$2459,$Z2401) -> 35.14 | Q2401: =INDEX(Datos_Origen!$J$2:$J$2459,$Z2401) -> 18.39 | R2401: =ROUND($O2401*$P2401,2) -> 597.38 | S2401: =ROUND($O2401*$Q2401,2) -> 312.63 | T2401: =ROUND($R2401*SUMIFS(Parametros!$E$28:$E$43,Parametros!$B$28:$B$43,$J2401,Parametros!$C$28:$C$43,$C2401,Parametros!$D$28:$D$43,$D2401),2) -> 31.06 | U2401: =$R2401-$S2401-$T2401 -> 253.69 | V2401: =IFERROR($U2401/$R2401,0) -> 0.42467106 | W2401: =IF(AND($V2401>=Parametros!$C$8,$R2401>=Parametros!$C$12),"Alta rentabilidad",IF(OR($V2401<Parametros!$C$11,$R2401<Parametros!$C$13),"Revisar","Estandar")) -> Estandar | X2401: =IF(AND($J2401="E-commerce",IFERROR($T2401/$R2401,0)>Parametros!$C$14),"Alerta","OK") -> Alerta | Y2401: =IF($R2401>=Parametros!$C$12,"Alto",IF($R2401<Parametros!$C$13,"Bajo","Medio")) -> Medio | Z2401: 2149 | AA2401: =IF(MATCH($A2401,Datos_Origen!$A$2:$A$2459,0)=$Z2401,"OK","REVISAR") -> OK | AB2401: =INDEX(Datos_Origen!$B$2:$B$2459,$Z2401) -> 45998 | AC2401: =INDEX(Datos_Origen!$H$2:$H$2459,$Z2401) -> 17 | AD2401: =INDEX(Datos_Origen!$D$2:$D$2459,$Z2401)&"" -> Tucuman

Sheet Datos_Origen
A1: ID_Venta | B1: Fecha | C1: Region | D1: Ciudad | E1: Canal | F1: Categoria | G1: Producto | H1: Unidades | I1: Precio_Unitario | J1: Costo_Unitario | K1: Ventas_Origen
A2: 1724 | B2: 45835 | C2: Centro | D2: Cordoba | E2: e-commerce | F2: computación | G2: Monitor 4K 27 | H2: 10 | I2: 433.15 | J2: 280.42 | K2: =IF(ISTEXT(H2),VALUE(H2),H2)*I2 -> 4331.5 | N2: EXPORT CRUDO · NO EDITAR · entrada del proceso
A3: 639 | B3: 45492 | C3: Centro | D3: Cordoba | E3: Tienda fisica | F3: Almacenamiento | G3: Pendrive 256GB | H3: 30 | I3: 34.3 | J3: 17.85 | K3: =IF(ISTEXT(H3),VALUE(H3),H3)*I3 -> 1029
A4: 8 | B4: 03/01/2024 | C4: A.M.B.A. | D4: Buenos Aires | E4: E-COMMERCE | F4: accesorios | G4: Mouse Inalambrico | H4: 30 | I4: 27.44 | J4: 13.44 | K4: =IF(ISTEXT(H4),VALUE(H4),H4)*I4 -> 823.2 | N4: Que es esta hoja
A5: 1807 | B5: 45852 | C5: A.M.B.A. | D5: Buenos Aires | E5: TIENDA FISICA | F5: Accesorios | G5: Mouse Inalambrico | H5: 95 | I5: 28.11 | J5: 13.84 | K5: =IF(ISTEXT(H5),VALUE(H5),H5)*I5 -> 2670.45 | N5: El archivo tal como lo entrega el sistema transaccional. Se deja intacto a proposito: es la evidencia de que la limpieza se hizo y permite rehacerla si cambia una regla.
A6: 1511 | B6: 45768 | C6: A.M.B.A. | D6: Buenos Aires | E6: Tienda fisica | F6: Accesorios | G6: Webcam Full HD | H6: 86 | I6: 64.58 | J6: 36.49 | K6: =IF(ISTEXT(H6),VALUE(H6),H6)*I6 -> 5553.88
A7: 836 | B7: 21/09/2024 | C7: Centro | D7: Cordoba | E7: E-commerce | F7: Audio | G7: Parlante Bluetooth | H7: 12 | I7: 83.3 | J7: 48.03 | K7: =IF(ISTEXT(H7),VALUE(H7),H7)*I7 -> 999.6
A8: 1355 | B8: 45697 | C8: LITORAL | D8: Rosario | E8: tienda fisica | F8: Audio | G8: Parlante Bluetooth | H8: 15 | I8: 84.46 | J8: 49.47 | K8: =IF(ISTEXT(H8),VALUE(H8),H8)*I8 -> 1266.9
A9: 1387 | B9: 45705 | C9: NOA | D9: Tucuman | E9: tienda fisica | F9: Accesorios | G9: Mouse Inalambrico | H9: 25 | I9: 27.82 | J9: 13.84 | K9: =IF(ISTEXT(H9),VALUE(H9),H9)*I9 -> 695.5 | N9: Las celdas ambar
A10: 516 | B10: 45465 | C10: AMBA | D10: Buenos Aires | E10: E-commerce | F10: AUDIO | G10: Parlante Bluetooth | H10: 17 | I10: 83.3 | J10: 48.03 | K10: =IF(ISTEXT(H10),VALUE(H10),H10)*I10 -> 1416.1 | N10: Estan resaltadas por formato condicional. Marcan los cuatro defectos: ID repetido, fecha cargada como texto, unidades cargadas como texto y ciudad vacia.
A11: 1948 | B11: 45871 | C11: Litoral | D11: Rosario | E11: Ecommerce | F11: Accesorios | G11: Mouse Inalambrico | H11: 25 | I11: 28.11 | J11: 13.84 | K11: =IF(ISTEXT(H11),VALUE(H11),H11)*I11 -> 702.75
A12: 1223 | B12: 45660 | C12: CENTRO | D12: Cordoba | E12: Tienda Fisica | F12: Computacion | G12: Monitor 4K 27 | H12: 9 | I12: 433.15 | J12: 280.42 | K12: =IF(ISTEXT(H12),VALUE(H12),H12)*I12 -> 3898.35
A13: 808 | B13: 14/09/2024 | C13: AMBA | D13: Buenos Aires | E13: E-commerce | F13: accesorios | G13: Mouse Inalambrico | H13: 45 | I13: 27.44 | J13: 13.44 | K13: =IF(ISTEXT(H13),VALUE(H13),H13)*I13 -> 1234.8
A14: 1058 | B14: 09/11/2024 | C14: LITORAL | D14: Rosario | E14: E-COMMERCE | F14: Almacenamiento | G14: SSD Externo 1TB | H14: 13 | I14: 127.4 | J14: 76.05 | K14: =IF(ISTEXT(H14),VALUE(H14),H14)*I14 -> 1656.2 | N14: Los textos sin estandarizar
A15: 1757 | B15: 2025-06-15 | C15: Litoral | D15: Rosario | E15: TIENDA FISICA | F15: Almacenamiento | G15: SSD Externo 1TB | H15: 24 | I15: 129.17 | J15: 78.33 | K15: =IF(ISTEXT(H15),VALUE(H15),H15)*I15 -> 3100.08 | N15: Region, Canal y Categoria llegan con mayusculas, minusculas, acentos y espacios mezclados. El diccionario de la hoja Parametros los unifica.
A16: 1383 | B16: 16/02/2025 | C16: Noa | E16: Tienda física | F16: Computación | G16: Monitor 4K 27 | H16: 6 | I16: 433.15 | J16: 280.42 | K16: =IF(ISTEXT(H16),VALUE(H16),H16)*I16 -> 2598.9
A17: 1261 | B17: 45683 | C17: Cuyo | D17: Mendoza | E17: Tienda fisica | F17: COMPUTACION | G17: Laptop Pro 15 | H17: 6 | I17: 1155.06 | J17: 766.32 | K17: =IF(ISTEXT(H17),VALUE(H17),H17)*I17 -> 6930.36
A18: 206 | B18: 2024-03-12 | C18: A.M.B.A. | D18: Buenos Aires | E18: Ecommerce | F18: computación | G18: PC Gamer Ryzen | H18: 8 | I18: 1617 | J18: 1122 | K18: =IF(ISTEXT(H18),VALUE(H18),H18)*I18 -> 12936
A19: 2192 | B19: 45939 | C19: noa | D19: Tucuman | E19: E-commerce | F19: ACCESORIOS | G19: Webcam Full HD | H19: 22 | I19: 65.26 | J19: 36.49 | K19: =IF(ISTEXT(H19),VALUE(H19),H19)*I19 -> 1435.72 | N19: Que pasa despues
A20: 1083 | B20: 22/11/2024 | C20: NOA | D20: Tucuman | E20: Tienda fisica | F20: Computacion | G20: Monitor 4K 27 | H20: 8 | I20: 441 | J20: 272.25 | K20: =IF(ISTEXT(H20),VALUE(H20),H20)*I20 -> 3528 | N20: La hoja Datos_Limpios reconstruye cada fila con formulas y la hoja Control_Calidad verifica que no quede ningun defecto.
A21: 101 | B21: 45328 | C21: amba | D21: Buenos Aires | E21: Tienda fisica | F21: Computación | G21: Laptop Pro 15 | H21: 18 | I21: 1176 | J21: 744 | K21: =IF(ISTEXT(H21),VALUE(H21),H21)*I21 -> 21168
A22: 641 | B22: 45479 | C22: litoral | D22: Rosario | E22: TIENDA FISICA | F22: computacion | G22: Laptop Pro 15 | H22: 10 | I22: 1176 | J22: 744 | K22: =IF(ISTEXT(H22),VALUE(H22),H22)*I22 -> 11760
A23: 749 | B23: 45510 | C23: Litoral | D23: Rosario | E23: TIENDA FISICA | F23: ACCESORIOS | G23: Teclado Mecanico | H23: 33 | I23: 93.1 | J23: 47.98 | K23: =IF(ISTEXT(H23),VALUE(H23),H23)*I23 -> 3072.3
A24: 2024 | B24: 45921 | C24: Centro | D24: Cordoba | E24: E-commerce | F24: Computacion | G24: Monitor 4K 27 | H24: 9 | I24: 451.78 | J24: 280.42 | K24: =IF(ISTEXT(H24),VALUE(H24),H24)*I24 -> 4066.02
A25: 1229 | B25: 45675 | C25: Centro | D25: Cordoba | E25: Tienda fisica | F25: accesorios | G25: Teclado Mecanico | H25: 39 | I25: 94.39 | J25: 49.41 | K25: =IF(ISTEXT(H25),VALUE(H25),H25)*I25 -> 3681.21
A26: 954 | B26: 45575 | C26: Litoral | D26: Rosario | E26: e-commerce | F26: AUDIO | G26: Auriculares BT Pro | H26: 7 | I26: 117.6 | J26: 63.6 | K26: =IF(ISTEXT(H26),VALUE(H26),H26)*I26 -> 823.2
A27: 2306 | B27: 46015 | C27: AMBA | D27: Buenos Aires | E27: e-commerce | F27: computación | G27: PC Gamer Ryzen | H27: 21 | I27: 1656.52 | J27: 1155.66 | K27: =IF(ISTEXT(H27),VALUE(H27),H27)*I27 -> 34786.92
A28: 1821 | B28: 04/07/2025 | C28: centro | D28: Cordoba | E28: Tienda fisica | F28: COMPUTACION | G28: Laptop Pro 15 | H28: 14 | I28: 1204.74 | J28: 766.32 | K28: =IF(ISTEXT(H28),VALUE(H28),H28)*I28 -> 16866.36
A29: 1394 | B29: 12/02/2025 | C29: NOA | D29: Tucuman | E29: E-commerce | F29: audio | G29: Auriculares BT Pro | H29: 7 | I29: 119.23 | J29: 65.51 | K29: =IF(ISTEXT(H29),VALUE(H29),H29)*I29 -> 834.61
A30: 23 | B30: 27/01/2024 | C30: Centro | D30: Cordoba | E30: Tienda física | F30: Computación | G30: Monitor 4K 27 | H30: 9 | I30: 441 | J30: 272.25 | K30: =IF(ISTEXT(H30),VALUE(H30),H30)*I30 -> 3969
A31: 2249 | B31: 45964 | C31: litoral | D31: Rosario | E31: TIENDA FISICA | F31: Accesorios | G31: Teclado Mecanico | H31: 45 | I31: 95.38 | J31: 49.41 | K31: =IF(ISTEXT(H31),VALUE(H31),H31)*I31 -> 4292.1
A32: 922 | B32: 45567 | C32: Centro | D32: Cordoba | E32: e-commerce | F32: Computacion | G32: Laptop Pro 15 | H32: 5 | I32: 1176 | J32: 744 | K32: =IF(ISTEXT(H32),VALUE(H32),H32)*I32 -> 5880
A33: 857 | B33: 06/09/2024 | C33: litoral | D33: Rosario | E33: tienda fisica | F33: Almacenamiento | G33: SSD Externo 1TB | H33: 21 | I33: 127.4 | J33: 76.05 | K33: =IF(ISTEXT(H33),VALUE(H33),H33)*I33 -> 2675.4
A34: 1695 | B34: 13/05/2025 | C34: noa | D34: Tucuman | E34: TIENDA FISICA | F34: Audio | G34: Parlante Bluetooth | H34: 13 | I34: 84.46 | J34: 49.47 | K34: =IF(ISTEXT(H34),VALUE(H34),H34)*I34 -> 1097.98
A35: 843 | B35: 16/09/2024 | C35: Litoral | E35: Tienda fisica | F35: computación | G35: Monitor 4K 27 | H35: 10 | I35: 441 | J35: 272.25 | K35: =IF(ISTEXT(H35),VALUE(H35),H35)*I35 -> 4410
A36: 798 | B36: 45529 | C36: noa | D36: Tucuman | E36: E-COMMERCE | F36: ALMACENAMIENTO | G36: SSD Externo 1TB | H36: 8 | I36: 127.4 | J36: 76.05 | K36: =IF(ISTEXT(H36),VALUE(H36),H36)*I36 -> 1019.2
A37: 2141 | B37: 45933 | C37: LITORAL | D37: Rosario | E37: Tienda fisica | F37: Computación | G37: Laptop Pro 15 | H37: 8 | I37: 1204.74 | J37: 766.32 | K37: =IF(ISTEXT(H37),VALUE(H37),H37)*I37 -> 9637.92
A38: 113 | B38: 2024-02-09 | C38: Amba | D38: Buenos Aires | E38: Tienda Fisica | F38: Audio | G38: Auriculares BT Pro | H38: 40 | I38: 117.6 | J38: 63.6 | K38: =IF(ISTEXT(H38),VALUE(H38),H38)*I38 -> 4704
A39: 830 | B39: 45541 | C39: Centro | D39: Cordoba | E39: E-commerce | F39: accesorios | G39: Teclado Mecanico | H39: 26 | I39: 93.1 | J39: 47.98 | K39: =IF(ISTEXT(H39),VALUE(H39),H39)*I39 -> 2420.6
A40: 1924 | B40: 2025-08-23 | C40: Centro | D40: Cordoba | E40: E-commerce | F40: Computacion | G40: Monitor 4K 27 | H40: 8 | I40: 451.78 | J40: 280.42 | K40: =IF(ISTEXT(H40),VALUE(H40),H40)*I40 -> 3614.24
...

Sheet Control_Calidad
B2: Control de calidad del dato
B3: Cada fila mide un defecto del export crudo y verifica que despues del ETL ya no exista. Todos los numeros son formulas sobre las hojas Datos_Origen y Datos_Limpios: si el origen cambia, este tablero se actualiza solo. Nota: CONTAR.SI no distingue mayusculas de minusculas, asi que las cuentas de valores distintos son un piso; el diccionario de Parametros publica todas las variantes recibidas, una por fila.
B6: DIAGNOSTICO Y REMEDIACION
B7: Problema de calidad | C7: Regla aplicada | D7: En el origen | E7: Despues del ETL | F7: Estado
B8: Registros duplicados | C8: Se conserva la primera aparicion de cada ID_Venta y se descartan los reenvios del sistema. | D8: =2458-SUMPRODUCT((Datos_Origen!$A$2:$A$2459<>"")/COUNTIF(Datos_Origen!$A$2:$A$2459,Datos_Origen!$A$2:$A$2459&"")) -> 58 | E8: =2400-SUMPRODUCT((Datos_Limpios!$A$2:$A$2401<>"")/COUNTIF(Datos_Limpios!$A$2:$A$2401,Datos_Limpios!$A$2:$A$2401&"")) -> 0 | F8: =IF(E8=0,"OK","REVISAR") -> OK
B9: Fechas almacenadas como texto | C9: Se detecta el formato (dd/mm/aaaa o aaaa-mm-dd) y se reconstruye la fecha real con FECHA/DATE. | D9: =SUMPRODUCT(--ISTEXT(Datos_Origen!$B$2:$B$2459)) -> 845 | E9: =SUMPRODUCT(--ISTEXT(Datos_Limpios!$B$2:$B$2401)) -> 0 | F9: =IF(E9=0,"OK","REVISAR") -> OK
B10: Unidades cargadas como texto | C10: Se convierten a numero con VALOR/VALUE solo cuando la celda es texto. | D10: =SUMPRODUCT(--ISTEXT(Datos_Origen!$H$2:$H$2459)) -> 246 | E10: =SUMPRODUCT(--ISTEXT(Datos_Limpios!$O$2:$O$2401)) -> 0 | F10: =IF(E10=0,"OK","REVISAR") -> OK
B11: Ciudades vacias | C11: Se completan con la ciudad de referencia de la region (INDICE/COINCIDIR contra Parametros). | D11: =COUNTBLANK(Datos_Origen!$D$2:$D$2459) -> 159 | E11: =COUNTBLANK(Datos_Limpios!$I$2:$I$2401) -> 0 | F11: =IF(E11=0,"OK","REVISAR") -> OK
B12: Valores distintos en Categoria | C12: Diccionario de normalizacion: cada variante recibida se mapea a un unico valor estandar. Deben quedar tantos valores como categorias reales. | D12: =SUMPRODUCT((Datos_Origen!$F$2:$F$2459<>"")/COUNTIF(Datos_Origen!$F$2:$F$2459,Datos_Origen!$F$2:$F$2459&"")) -> 11 | E12: =SUMPRODUCT((Datos_Limpios!$K$2:$K$2401<>"")/COUNTIF(Datos_Limpios!$K$2:$K$2401,Datos_Limpios!$K$2:$K$2401&"")) -> 4 | F12: =IF(E12=4,"OK","REVISAR") -> OK
B13: Valores distintos en Region | C13: Mismo diccionario, dimension Region. | D13: =SUMPRODUCT((Datos_Origen!$C$2:$C$2459<>"")/COUNTIF(Datos_Origen!$C$2:$C$2459,Datos_Origen!$C$2:$C$2459&"")) -> 11 | E13: =SUMPRODUCT((Datos_Limpios!$H$2:$H$2401<>"")/COUNTIF(Datos_Limpios!$H$2:$H$2401,Datos_Limpios!$H$2:$H$2401&"")) -> 5 | F13: =IF(E13=5,"OK","REVISAR") -> OK
B14: Valores distintos en Canal | C14: Mismo diccionario, dimension Canal. | D14: =SUMPRODUCT((Datos_Origen!$E$2:$E$2459<>"")/COUNTIF(Datos_Origen!$E$2:$E$2459,Datos_Origen!$E$2:$E$2459&"")) -> 7 | E14: =SUMPRODUCT((Datos_Limpios!$J$2:$J$2401<>"")/COUNTIF(Datos_Limpios!$J$2:$J$2401,Datos_Limpios!$J$2:$J$2401&"")) -> 2 | F14: =IF(E14=2,"OK","REVISAR") -> OK
B15: Valores distintos en Producto | C15: ESPACIOS/TRIM sobre el nombre recibido. | D15: =SUMPRODUCT((Datos_Origen!$G$2:$G$2459<>"")/COUNTIF(Datos_Origen!$G$2:$G$2459,Datos_Origen!$G$2:$G$2459&"")) -> 30 | E15: =SUMPRODUCT((Datos_Limpios!$M$2:$M$2401<>"")/COUNTIF(Datos_Limpios!$M$2:$M$2401,Datos_Limpios!$M$2:$M$2401&"")) -> 10 | F15: =IF(E15=10,"OK","REVISAR") -> OK
B17: RECONCILIACION
B18: Concepto | C18: Detalle | D18: Valor
B19: Filas recibidas en el export | C19: Todo lo que entrego el sistema, reenvios incluidos. | D19: =COUNTA(Datos_Origen!$A$2:$A$2459) -> 2458
B20: Operaciones unicas | C20: Filas distintas por ID_Venta: lo que realmente ocurrio. | D20: =SUMPRODUCT((Datos_Origen!$A$2:$A$2459<>"")/COUNTIF(Datos_Origen!$A$2:$A$2459,Datos_Origen!$A$2:$A$2459&"")) -> 2400
B21: Filas descartadas por duplicado | C21: Diferencia entre las dos anteriores. | D21: =D19-D20 -> 58
B22: Facturacion del export crudo | C22: Unidades x precio sobre TODAS las filas recibidas. | D22: =SUM(Datos_Origen!$K$2:$K$2459) -> 10550977
B23: Facturacion depurada | C23: La misma cuenta sobre la tabla limpia. | D23: =SUM(Datos_Limpios!$R$2:$R$2401) -> 10292360
B24: Facturacion que inflaban los duplicados | C24: Lo que se habria reportado de mas sin depurar. | D24: =D22-D23 -> 258616.33
B25: Filas de la tabla limpia | C25: Debe coincidir con las operaciones unicas. | D25: =COUNTA(Datos_Limpios!$A$2:$A$2401) -> 2400
B26: Control de deduplicacion | C26: Filas donde Pos_Origen NO apunta a la primera aparicion del ID_Venta. Tiene que ser cero. | D26: =COUNTIF(Datos_Limpios!$AA$2:$AA$2401,"REVISAR") -> 0 | E26: =IF(D26=0,"OK","REVISAR") -> OK
B28: COLUMNAS QUE AGREGA EL ETL
B29: Columna calculada | C29: Regla | D29: Resultado
B30: Segmento_Rentabilidad | C30: SI(Y(margen% >= meta; ventas >= ticket alto); "Alta rentabilidad"; SI(O(margen% < piso; ventas < ticket bajo); "Revisar"; "Estandar")) | D30: Alta rentabilidad | E30: =COUNTIF(Datos_Limpios!$W$2:$W$2401,"Alta rentabilidad") -> 521
D31: Estandar | E31: =COUNTIF(Datos_Limpios!$W$2:$W$2401,"Estandar") -> 1655
D32: Revisar | E32: =COUNTIF(Datos_Limpios!$W$2:$W$2401,"Revisar") -> 224
B34: Alerta_Logistica | C34: SI(Y(canal = "E-commerce"; costo logistico / ventas > techo); "Alerta"; "OK") | D34: Alerta | E34: =COUNTIF(Datos_Limpios!$X$2:$X$2401,"Alerta") -> 600
D35: OK | E35: =COUNTIF(Datos_Limpios!$X$2:$X$2401,"OK") -> 1800
B37: Ticket | C37: SI(ventas >= ticket alto; "Alto"; SI(ventas < ticket bajo; "Bajo"; "Medio")) | D37: Alto | E37: =COUNTIF(Datos_Limpios!$Y$2:$Y$2401,"Alto") -> 965
D38: Medio | E38: =COUNTIF(Datos_Limpios!$Y$2:$Y$2401,"Medio") -> 1406
D39: Bajo | E39: =COUNTIF(Datos_Limpios!$Y$2:$Y$2401,"Bajo") -> 29
B42: Las tres columnas anteriores se calculan con logica condicional (SI / Y / O) sobre los umbrales de la hoja Parametros. Cambiar un umbral reclasifica las 2.400 operaciones sin tocar una sola formula.

Sheet Parametros
B2: Parametros, supuestos, metas y diccionarios
B3: Toda constante del modelo vive en esta hoja. El ETL, los KPIs y las columnas logicas la referencian por celda; ninguna la repite escrita a mano. | H3: MESES | K3: LISTAS DE VALIDACION
H4: N | I4: Mes | K4: Region | L4: Categoria | M4: Anio
B5: METAS Y UMBRALES DEL EJERCICIO 2025 | H5: 1 | I5: Ene | K5: AMBA | L5: Computacion | M5: Todos
B6: Indicador | C6: Valor | D6: Se usa en | F6: Origen del supuesto | H6: 2 | I6: Feb | K6: Centro | L6: Accesorios | M6: 2024
B7: Ventas totales 2025 (meta) | C7: 5400000 | D7: KPI 1 | F7: Presupuesto comercial aprobado para el ejercicio. | H7: 3 | I7: Mar | K7: Litoral | L7: Audio | M7: 2025
B8: Margen bruto % (meta) | C8: 0.34 | D8: KPI 2 / columna logica | F8: Piso historico de la cadena: 2024 cerro en 35,8%. | H8: 4 | I8: Abr | K8: Cuyo | L8: Almacenamiento
B9: Crecimiento interanual de ventas (meta) | C9: 0.15 | D9: KPI 3 | F9: Objetivo de expansion fijado por la direccion. | H9: 5 | I9: May | K9: NOA
B10: Costo logistico sobre ventas (techo) | C10: 0.025 | D10: KPI 4 | F10: Techo tolerado a nivel compania; 2024 cerro en 2,18%. | H10: 6 | I10: Jun
B11: Margen bruto % piso por operacion | C11: 0.28 | D11: Columna Segmento_Rentabilidad | F11: Por debajo de este margen la operacion entra en revision comercial. | H11: 7 | I11: Jul | K11: Alimentan las listas desplegables del bloque de consulta de la hoja Tablas_Dinamicas.
B12: Ticket alto (USD) | C12: 3000 | D12: Columnas Segmento_Rentabilidad y Ticket | F12: Corte de venta grande: por encima requiere aprobacion de gerencia. | H12: 8 | I12: Ago
B13: Ticket bajo (USD) | C13: 300 | D13: Columnas Segmento_Rentabilidad y Ticket | F13: Por debajo el costo de atencion se come el margen. | H13: 9 | I13: Sep
B14: Costo logistico / ventas tolerado en e-commerce | C14: 0.05 | D14: Columna Alerta_Logistica | F14: Umbral operativo de la ultima milla en el canal online. | H14: 10 | I14: Oct
B15: Margen bruto % minimo por producto | C15: 0.33 | D15: Grafico de dispersion | F15: Corte que separa la zona de riesgo en el mapa de productos. | H15: 11 | I15: Nov
H16: 12 | I16: Dic
B17: SUPUESTOS DEL DATASET
B18: Periodo cubierto | C18: Ene-2024 a Dic-2025 | F18: Dataset SIMULADO y determinista (semilla fija). Extiende el modelo Ventas_Tech_DB del checkpoint de SQL -mismas categorias, productos y ciudades- a 24 meses, 5 regiones y 2 canales, para poder analizar margen, estacionalidad y evolucion interanual. | H18: CIUDAD POR REGION
B19: Operaciones unicas (tabla de hechos) | C19: 2400 | H19: Region | I19: Ciudad
B20: Aumento de precio de lista 2025 | C20: 0.035 | H20: AMBA | I20: Buenos Aires
B21: Inflacion de costo de compra 2025 | C21: 0.03 | H21: Centro | I21: Cordoba
B22: Crecimiento de unidades 2025 | C22: 0.155 | H22: Litoral | I22: Rosario
B23: Participacion de e-commerce 2024 | C23: 0.28 | H23: Cuyo | I23: Mendoza
B24: Participacion de e-commerce 2025 | C24: 0.41 | H24: NOA | I24: Tucuman
B26: COSTO LOGISTICO SOBRE VENTAS · tasa que aplica el ETL | H26: Se usa para completar las ciudades que el export deja vacias.
B27: Canal | C27: Anio | D27: Trimestre | E27: Tasa
B28: Tienda fisica | C28: 2024 | D28: Q1 | E28: 0.012 | F28: El salto de e-commerce en 2025 (ultima milla y envio bonificado) y su baja en Q3-Q4 al fijar un umbral de envio minimo es el hecho que explica la caida y posterior recuperacion del margen.
B29: Tienda fisica | C29: 2024 | D29: Q2 | E29: 0.012
B30: Tienda fisica | C30: 2024 | D30: Q3 | E30: 0.013
B31: Tienda fisica | C31: 2024 | D31: Q4 | E31: 0.013
B32: Tienda fisica | C32: 2025 | D32: Q1 | E32: 0.013
B33: Tienda fisica | C33: 2025 | D33: Q2 | E33: 0.014
B34: Tienda fisica | C34: 2025 | D34: Q3 | E34: 0.013
B35: Tienda fisica | C35: 2025 | D35: Q4 | E35: 0.013
B36: E-commerce | C36: 2024 | D36: Q1 | E36: 0.042
B37: E-commerce | C37: 2024 | D37: Q2 | E37: 0.044
B38: E-commerce | C38: 2024 | D38: Q3 | E38: 0.046
B39: E-commerce | C39: 2024 | D39: Q4 | E39: 0.048
B40: E-commerce | C40: 2025 | D40: Q1 | E40: 0.068
... B43: E-commerce | C43: 2025 | D43: Q4 | E43: 0.052
B46: DICCIONARIO DE NORMALIZACION DE TEXTO · valor recibido -> valor estandar
...

Sheet Documentacion
B2: Documentacion del libro
B3: Practica Integradora Final · Coderhouse, Data Analyst · Lleyton Murphy
B5: MAPA DEL LIBRO
B6: Hoja | C6: Rol | D6: Que contiene
B7: Dashboard | C7: El entregable | D7: Titular, 4 tarjetas de KPI, 4 segmentadores, 5 graficos y el reporte ejecutivo. Se abre en esta hoja.
B8: Tablas_Dinamicas | C8: Analisis | D8: Las 4 tablas dinamicas del reporte mas un bloque de consulta con listas desplegables.
B9: Datos_Limpios | C9: Tabla de hechos | D9: 2.400 operaciones depuradas. Cada celda es una formula que reconstruye el valor desde el export crudo.
B10: Datos_Origen | C10: Entrada | D10: El export del sistema transaccional, sin tocar. Los defectos estan resaltados con formato condicional.
B11: Control_Calidad | C11: Auditoria | D11: Cuenta los defectos del origen y verifica con formulas que despues del ETL no quede ninguno.
B12: Parametros | C12: Constantes | D12: Metas, umbrales, tasas, diccionarios de normalizacion y listas de validacion. Ningun numero fijo vive fuera de aca.
B13: Documentacion | C13: Esta hoja | D13: Como esta hecho y como se opera.
B14: Calculos (oculta) | C14: Soporte | D14: Grilla de tamano fijo resuelta con GETPIVOTDATA. Es lo que leen los graficos.
B15: Pivots_Aux (oculta) | C15: Soporte | D15: Tablas dinamicas de una sola medida que alimentan a GETPIVOTDATA.
B17: EL ETL, PASO A PASO · de Datos_Origen a Datos_Limpios
B18: Paso | C18: Funciones usadas | D18: Que hace y por que
B19: 1. Quitar duplicados | C19: COINCIDIR / MATCH | D19: El sistema reenvia lotes y repite filas. Se conserva la primera aparicion de cada ID_Venta. La columna Pos_Origen guarda a que fila del export apunta cada operacion y la columna Control_ETL verifica, fila por fila, que esa sea de verdad la primera aparicion.
B20: 2. Normalizar fechas | C20: SI, ESNUMERO, EXTRAE, FECHA, VALOR | D20: El export mezcla tres formatos: fecha real, texto dd/mm/aaaa y texto aaaa-mm-dd. La formula detecta cual es cada uno y reconstruye una fecha real. Sin esto no hay agrupacion por mes ni por trimestre que funcione.
B21: 3. Estandarizar textos | C21: ESPACIOS, INDICE, COINCIDIR | D21: Region, Canal y Categoria llegan con mayusculas, minusculas, acentos y espacios mezclados. Se resuelven contra el diccionario de la hoja Parametros. Agregar una variante nueva es agregar una fila al diccionario: no hay que tocar ninguna formula.
B22: 4. Corregir tipos | C22: SI, ESTEXTO, VALOR | D22: Algunas unidades llegan como texto. Se convierten a numero solo cuando hace falta, para no romper las que ya venian bien.
B23: 5. Completar vacios | C23: SI, ESPACIOS, INDICE, COINCIDIR | D23: Las ciudades vacias se completan con la ciudad de referencia de la region. Se documenta como imputacion, no se presenta como dato original.
B24: 6. Derivar columnas | C24: ANIO, MES, REDONDEAR.MAS, TEXTO | D24: Anio, Trimestre, Mes, Periodo, Cat_Anio y Prod_Anio salen de la fecha y de los textos ya limpios. Son las que hacen posible el analisis temporal y la comparacion interanual.
B25: 7. Calcular medidas | C25: REDONDEAR, SUMAR.SI.CONJUNTO | D25: Ventas, Costo_Producto, Costo_Logistico y Margen_Bruto se calculan en la planilla, no se pegan como numeros. La tasa logistica no se repite fila a fila: se busca en la tabla de Parametros segun canal, anio y trimestre.
B26: 8. Clasificar | C26: SI, Y, O | D26: Tres columnas de logica condicional: Segmento_Rentabilidad, Alerta_Logistica y Ticket. Son las que convierten un numero en una decision, y son ademas dimensiones de analisis en las tablas dinamicas.
B28: LAS COLUMNAS CALCULADAS CON LOGICA CONDICIONAL
B29: Columna | C29: Regla | D29: Para que sirve
B30: Segmento_Rentabilidad | C30: SI(Y(margen% >= meta; ventas >= ticket alto); "Alta rentabilidad"; SI(O(margen% < piso; ventas < ticket bajo); "Revisar"; "Estandar")) | D30: Separa las operaciones que sostienen el negocio de las que hay que revisar. Usa Y para exigir las dos condiciones a la vez y O para que alcance con una sola para marcar el problema. Es la dimension de la cuarta tabla dinamica.
B31: Alerta_Logistica | C31: SI(Y(canal = "E-commerce"; costo logistico / ventas > techo); "Alerta"; "OK") | D31: Marca las ventas online cuyo costo de envio se sale del umbral operativo. Es el detalle fila a fila de lo que el KPI de costo logistico muestra agregado.
B32: Ticket | C32: SI(ventas >= ticket alto; "Alto"; SI(ventas < ticket bajo; "Bajo"; "Medio")) | D32: Clasifica el tamano de cada operacion. Permite mirar el mix de tickets sin recalcular nada.
B33: Donde estan los umbrales | C33: Parametros!C11:C14 | D33: Los cuatro cortes viven en la hoja Parametros. Cambiar un umbral reclasifica las 2.400 operaciones y actualiza las tablas dinamicas sin tocar una sola formula.
B35: COMO VIAJA UN FILTRO HASTA UN GRAFICO
B36: La cadena | C36: segmentador -> tabla dinamica -> GETPIVOTDATA (Calculos) -> grafico | D36: Los graficos no leen la tabla de hechos: leen una grilla de tamano fijo en la hoja Calculos, resuelta con GETPIVOTDATA contra las tablas dinamicas. Por eso el layout no se rompe cuando un filtro deja menos filas, y por eso los numeros del tablero y los de la hoja Tablas_Dinamicas son siempre los mismos.
B37: Un unico cache | C37: 4 segmentadores, 17 tablas dinamicas | D37: Todas las tablas dinamicas del libro comparten un solo cache de datos. Eso es lo que hace que una sola seleccion recalcule a la vez las 4 tarjetas, los 5 graficos y las 4 tablas dinamicas visibles.
